Workbook

Sheet Datawrapper Format
A1: Datum | B1: year_month | C1: pollster | D1: Vladimir Zelenskiy (individual, scope-normalised) | E1: Valerii Zaluzhniy (individual, scope-normalised) | F1: Kyrylo Budanov (individual, scope-normalised) | G1: Pyotr Poroshenko (individual, scope-normalised) | H1: Vladimir Zelenskiy (full weighted 1mo avg) | I1: Valerii Zaluzhniy (full weighted 1mo avg) | J1: Kyrylo Budanov (full weighted 1mo avg) | K1: Pyotr Poroshenko (full weighted 1mo avg) | L1: Zelenskiy (smoothed avg) | M1: Zaluzhniy (smoothed avg) | N1: Budanov (smoothed avg) | O1: Poroshenko (smoothed avg)
A2: 2026-03-26 | B2: 2026-03-01 | C2: SOCIS | D2: =IF(SUMPRODUCT((Data!$D$2:$D$2277=A2)*(Data!$E$2:$E$2277=C2)*(Data!$M$2:$M$2277="Vladimir Zelenskiy"))>0,SUMPRODUCT((Data!$D$2:$D$2277=A2)*(Data!$E$2:$E$2277=C2)*(Data!$M$2:$M$2277="Vladimir Zelenskiy")*IF(ISNUMBER(Data!$W$2:$W$2277),Data!$W$2:$W$2277,0))/SUMPRODUCT((Data!$D$2:$D$2277=A2)*(Data!$E$2:$E$2277=C2)*(Data!$M$2:$M$2277="Vladimir Zelenskiy")),"") -> 29.3 | E2: =IF(SUMPRODUCT((Data!$D$2:$D$2277=A2)*(Data!$E$2:$E$2277=C2)*(Data!$M$2:$M$2277="Valerii Zaluzhniy"))>0,SUMPRODUCT((Data!$D$2:$D$2277=A2)*(Data!$E$2:$E$2277=C2)*(Data!$M$2:$M$2277="Valerii Zaluzhniy")*IF(ISNUMBER(Data!$W$2:$W$2277),Data!$W$2:$W$2277,0))/SUMPRODUCT((Data!$D$2:$D$2277=A2)*(Data!$E$2:$E$2277=C2)*(Data!$M$2:$M$2277="Valerii Zaluzhniy")),"") -> 25 | F2: =IF(SUMPRODUCT((Data!$D$2:$D$2277=A2)*(Data!$E$2:$E$2277=C2)*(Data!$M$2:$M$2277="Kyrylo Budanov"))>0,SUMPRODUCT((Data!$D$2:$D$2277=A2)*(Data!$E$2:$E$2277=C2)*(Data!$M$2:$M$2277="Kyrylo Budanov")*IF(ISNUMBER(Data!$W$2:$W$2277),Data!$W$2:$W$2277,0))/SUMPRODUCT((Data!$D$2:$D$2277=A2)*(Data!$E$2:$E$2277=C2)*(Data!$M$2:$M$2277="Kyrylo Budanov")),"") -> 13.7 | G2: =IF(SUMPRODUCT((Data!$D$2:$D$2277=A2)*(Data!$E$2:$E$2277=C2)*(Data!$M$2:$M$2277="Pyotr Poroshenko"))>0,SUMPRODUCT((Data!$D$2:$D$2277=A2)*(Data!$E$2:$E$2277=C2)*(Data!$M$2:$M$2277="Pyotr Poroshenko")*IF(ISNUMBER(Data!$W$2:$W$2277),Data!$W$2:$W$2277,0))/SUMPRODUCT((Data!$D$2:$D$2277=A2)*(Data!$E$2:$E$2277=C2)*(Data!$M$2:$M$2277="Pyotr Poroshenko")),"") -> 7.4 | H2: {=IFERROR(INDEX(Avg!$F$2:$F$50,MATCH(DATE(YEAR(A2),MONTH(A2),1),Avg!$A$2:$A$50,0)),"")} -> 28.781612 | I2: {=IFERROR(INDEX(Avg!$G$2:$G$50,MATCH(DATE(YEAR(A2),MONTH(A2),1),Avg!$A$2:$A$50,0)),"")} -> 25.209129 | J2: {=IFERROR(INDEX(Avg!$H$2:$H$50,MATCH(DATE(YEAR(A2),MONTH(A2),1),Avg!$A$2:$A$50,0)),"")} -> 10.613857 | K2: {=IFERROR(INDEX(Avg!$I$2:$I$50,MATCH(DATE(YEAR(A2),MONTH(A2),1),Avg!$A$2:$A$50,0)),"")} -> 8.8897622 | L2: {=IFERROR(INDEX(Avg!$L$2:$L$50,MATCH(DATE(YEAR(A2),MONTH(A2),1),Avg!$A$2:$A$50,0)),"")} -> 28.497204 | M2: {=IFERROR(INDEX(Avg!$M$2:$M$50,MATCH(DATE(YEAR(A2),MONTH(A2),1),Avg!$A$2:$A$50,0)),"")} -> 25.573807 | N2: {=IFERROR(INDEX(Avg!$N$2:$N$50,MATCH(DATE(YEAR(A2),MONTH(A2),1),Avg!$A$2:$A$50,0)),"")} -> 9.6178518 | O2: {=IFERROR(INDEX(Avg!$O$2:$O$50,MATCH(DATE(YEAR(A2),MONTH(A2),1),Avg!$A$2:$A$50,0)),"")} -> 9.2545957
A3: 2026-02-04 | B3: 2026-01-01 | C3: Active Group | D3: =IF(SUMPRODUCT((Data!$D$2:$D$2277=A3)*(Data!$E$2:$E$2277=C3)*(Data!$M$2:$M$2277="Vladimir Zelenskiy"))>0,SUMPRODUCT((Data!$D$2:$D$2277=A3)*(Data!$E$2:$E$2277=C3)*(Data!$M$2:$M$2277="Vladimir Zelenskiy")*IF(ISNUMBER(Data!$W$2:$W$2277),Data!$W$2:$W$2277,0))/SUMPRODUCT((Data!$D$2:$D$2277=A3)*(Data!$E$2:$E$2277=C3)*(Data!$M$2:$M$2277="Vladimir Zelenskiy")),"") -> 32.9 | E3: =IF(SUMPRODUCT((Data!$D$2:$D$2277=A3)*(Data!$E$2:$E$2277=C3)*(Data!$M$2:$M$2277="Valerii Zaluzhniy"))>0,SUMPRODUCT((Data!$D$2:$D$2277=A3)*(Data!$E$2:$E$2277=C3)*(Data!$M$2:$M$2277="Valerii Zaluzhniy")*IF(ISNUMBER(Data!$W$2:$W$2277),Data!$W$2:$W$2277,0))/SUMPRODUCT((Data!$D$2:$D$2277=A3)*(Data!$E$2:$E$2277=C3)*(Data!$M$2:$M$2277="Valerii Zaluzhniy")),"") -> 15.9 | F3: =IF(SUMPRODUCT((Data!$D$2:$D$2277=A3)*(Data!$E$2:$E$2277=C3)*(Data!$M$2:$M$2277="Kyrylo Budanov"))>0,SUMPRODUCT((Data!$D$2:$D$2277=A3)*(Data!$E$2:$E$2277=C3)*(Data!$M$2:$M$2277="Kyrylo Budanov")*IF(ISNUMBER(Data!$W$2:$W$2277),Data!$W$2:$W$2277,0))/SUMPRODUCT((Data!$D$2:$D$2277=A3)*(Data!$E$2:$E$2277=C3)*(Data!$M$2:$M$2277="Kyrylo Budanov")),"") -> 13.8 | G3: =IF(SUMPRODUCT((Data!$D$2:$D$2277=A3)*(Data!$E$2:$E$2277=C3)*(Data!$M$2:$M$2277="Pyotr Poroshenko"))>0,SUMPRODUCT((Data!$D$2:$D$2277=A3)*(Data!$E$2:$E$2277=C3)*(Data!$M$2:$M$2277="Pyotr Poroshenko")*IF(ISNUMBER(Data!$W$2:$W$2277),Data!$W$2:$W$2277,0))/SUMPRODUCT((Data!$D$2:$D$2277=A3)*(Data!$E$2:$E$2277=C3)*(Data!$M$2:$M$2277="Pyotr Poroshenko")),"") -> 10.9 | H3: {=IFERROR(INDEX(Avg!$F$2:$F$50,MATCH(DATE(YEAR(A3),MONTH(A3),1),Avg!$A$2:$A$50,0)),"")} -> 28.500372 | I3: {=IFERROR(INDEX(Avg!$G$2:$G$50,MATCH(DATE(YEAR(A3),MONTH(A3),1),Avg!$A$2:$A$50,0)),"")} -> 25.322587 | J3: {=IFERROR(INDEX(Avg!$H$2:$H$50,MATCH(DATE(YEAR(A3),MONTH(A3),1),Avg!$A$2:$A$50,0)),"")} -> 8.9395449 | K3: {=IFERROR(INDEX(Avg!$I$2:$I$50,MATCH(DATE(YEAR(A3),MONTH(A3),1),Avg!$A$2:$A$50,0)),"")} -> 9.6979968 | L3: {=IFERROR(INDEX(Avg!$L$2:$L$50,MATCH(DATE(YEAR(A3),MONTH(A3),1),Avg!$A$2:$A$50,0)),"")} -> 28.333617 | M3: {=IFERROR(INDEX(Avg!$M$2:$M$50,MATCH(DATE(YEAR(A3),MONTH(A3),1),Avg!$A$2:$A$50,0)),"")} -> 26.104611 | N3: {=IFERROR(INDEX(Avg!$N$2:$N$50,MATCH(DATE(YEAR(A3),MONTH(A3),1),Avg!$A$2:$A$50,0)),"")} -> 8.3388392 | O3: {=IFERROR(INDEX(Avg!$O$2:$O$50,MATCH(DATE(YEAR(A3),MONTH(A3),1),Avg!$A$2:$A$50,0)),"")} -> 9.2278448
A4: 2026-01-12 | B4: 2026-01-01 | C4: Active Group | D4: =IF(SUMPRODUCT((Data!$D$2:$D$2277=A4)*(Data!$E$2:$E$2277=C4)*(Data!$M$2:$M$2277="Vladimir Zelenskiy"))>0,SUMPRODUCT((Data!$D$2:$D$2277=A4)*(Data!$E$2:$E$2277=C4)*(Data!$M$2:$M$2277="Vladimir Zelenskiy")*IF(ISNUMBER(Data!$W$2:$W$2277),Data!$W$2:$W$2277,0))/SUMPRODUCT((Data!$D$2:$D$2277=A4)*(Data!$E$2:$E$2277=C4)*(Data!$M$2:$M$2277="Vladimir Zelenskiy")),"") -> 32.2 | E4: =IF(SUMPRODUCT((Data!$D$2:$D$2277=A4)*(Data!$E$2:$E$2277=C4)*(Data!$M$2:$M$2277="Valerii Zaluzhniy"))>0,SUMPRODUCT((Data!$D$2:$D$2277=A4)*(Data!$E$2:$E$2277=C4)*(Data!$M$2:$M$2277="Valerii Zaluzhniy")*IF(ISNUMBER(Data!$W$2:$W$2277),Data!$W$2:$W$2277,0))/SUMPRODUCT((Data!$D$2:$D$2277=A4)*(Data!$E$2:$E$2277=C4)*(Data!$M$2:$M$2277="Valerii Zaluzhniy")),"") -> 22.1 | F4: =IF(SUMPRODUCT((Data!$D$2:$D$2277=A4)*(Data!$E$2:$E$2277=C4)*(Data!$M$2:$M$2277="Kyrylo Budanov"))>0,SUMPRODUCT((Data!$D$2:$D$2277=A4)*(Data!$E$2:$E$2277=C4)*(Data!$M$2:$M$2277="Kyrylo Budanov")*IF(ISNUMBER(Data!$W$2:$W$2277),Data!$W$2:$W$2277,0))/SUMPRODUCT((Data!$D$2:$D$2277=A4)*(Data!$E$2:$E$2277=C4)*(Data!$M$2:$M$2277="Kyrylo Budanov")),"") -> 9.4 | G4: =IF(SUMPRODUCT((Data!$D$2:$D$2277=A4)*(Data!$E$2:$E$2277=C4)*(Data!$M$2:$M$2277="Pyotr Poroshenko"))>0,SUMPRODUCT((Data!$D$2:$D$2277=A4)*(Data!$E$2:$E$2277=C4)*(Data!$M$2:$M$2277="Pyotr Poroshenko")*IF(ISNUMBER(Data!$W$2:$W$2277),Data!$W$2:$W$2277,0))/SUMPRODUCT((Data!$D$2:$D$2277=A4)*(Data!$E$2:$E$2277=C4)*(Data!$M$2:$M$2277="Pyotr Poroshenko")),"") -> 10.4 | H4: {=IFERROR(INDEX(Avg!$F$2:$F$50,MATCH(DATE(YEAR(A4),MONTH(A4),1),Avg!$A$2:$A$50,0)),"")} -> 27.637642 | I4: {=IFERROR(INDEX(Avg!$G$2:$G$50,MATCH(DATE(YEAR(A4),MONTH(A4),1),Avg!$A$2:$A$50,0)),"")} -> 27.170279 | J4: {=IFERROR(INDEX(Avg!$H$2:$H$50,MATCH(DATE(YEAR(A4),MONTH(A4),1),Avg!$A$2:$A$50,0)),"")} -> 7.9864497 | K4: {=IFERROR(INDEX(Avg!$I$2:$I$50,MATCH(DATE(YEAR(A4),MONTH(A4),1),Avg!$A$2:$A$50,0)),"")} -> 9.4622939 | L4: {=IFERROR(INDEX(Avg!$L$2:$L$50,MATCH(DATE(YEAR(A4),MONTH(A4),1),Avg!$A$2:$A$50,0)),"")} -> 28.763061 | M4: {=IFERROR(INDEX(Avg!$M$2:$M$50,MATCH(DATE(YEAR(A4),MONTH(A4),1),Avg!$A$2:$A$50,0)),"")} -> 26.766213 | N4: {=IFERROR(INDEX(Avg!$N$2:$N$50,MATCH(DATE(YEAR(A4),MONTH(A4),1),Avg!$A$2:$A$50,0)),"")} -> 7.3844773 | O4: {=IFERROR(INDEX(Avg!$O$2:$O$50,MATCH(DATE(YEAR(A4),MONTH(A4),1),Avg!$A$2:$A$50,0)),"")} -> 8.3309527
A5: 2026-01-02 | B5: 2025-12-01 | C5: Ipsos | D5: =IF(SUMPRODUCT((Data!$D$2:$D$2277=A5)*(Data!$E$2:$E$2277=C5)*(Data!$M$2:$M$2277="Vladimir Zelenskiy"))>0,SUMPRODUCT((Data!$D$2:$D$2277=A5)*(Data!$E$2:$E$2277=C5)*(Data!$M$2:$M$2277="Vladimir Zelenskiy")*IF(ISNUMBER(Data!$W$2:$W$2277),Data!$W$2:$W$2277,0))/SUMPRODUCT((Data!$D$2:$D$2277=A5)*(Data!$E$2:$E$2277=C5)*(Data!$M$2:$M$2277="Vladimir Zelenskiy")),"") -> 25.641026 | E5: =IF(SUMPRODUCT((Data!$D$2:$D$2277=A5)*(Data!$E$2:$E$2277=C5)*(Data!$M$2:$M$2277="Valerii Zaluzhniy"))>0,SUMPRODUCT((Data!$D$2:$D$2277=A5)*(Data!$E$2:$E$2277=C5)*(Data!$M$2:$M$2277="Valerii Zaluzhniy")*IF(ISNUMBER(Data!$W$2:$W$2277),Data!$W$2:$W$2277,0))/SUMPRODUCT((Data!$D$2:$D$2277=A5)*(Data!$E$2:$E$2277=C5)*(Data!$M$2:$M$2277="Valerii Zaluzhniy")),"") -> 29.487179 | F5: =IF(SUMPRODUCT((Data!$D$2:$D$2277=A5)*(Data!$E$2:$E$2277=C5)*(Data!$M$2:$M$2277="Kyrylo Budanov"))>0,SUMPRODUCT((Data!$D$2:$D$2277=A5)*(Data!$E$2:$E$2277=C5)*(Data!$M$2:$M$2277="Kyrylo Budanov")*IF(ISNUMBER(Data!$W$2:$W$2277),Data!$W$2:$W$2277,0))/SUMPRODUCT((Data!$D$2:$D$2277=A5)*(Data!$E$2:$E$2277=C5)*(Data!$M$2:$M$2277="Kyrylo Budanov")),"") -> 8.974359 | G5: =IF(SUMPRODUCT((Data!$D$2:$D$2277=A5)*(Data!$E$2:$E$2277=C5)*(Data!$M$2:$M$2277="Pyotr Poroshenko"))>0,SUMPRODUCT((Data!$D$2:$D$2277=A5)*(Data!$E$2:$E$2277=C5)*(Data!$M$2:$M$2277="Pyotr Poroshenko")*IF(ISNUMBER(Data!$W$2:$W$2277),Data!$W$2:$W$2277,0))/SUMPRODUCT((Data!$D$2:$D$2277=A5)*(Data!$E$2:$E$2277=C5)*(Data!$M$2:$M$2277="Pyotr Poroshenko")),"") -> 11.538462 | H5: {=IFERROR(INDEX(Avg!$F$2:$F$50,MATCH(DATE(YEAR(A5),MONTH(A5),1),Avg!$A$2:$A$50,0)),"")} -> 27.637642 | I5: {=IFERROR(INDEX(Avg!$G$2:$G$50,MATCH(DATE(YEAR(A5),MONTH(A5),1),Avg!$A$2:$A$50,0)),"")} -> 27.170279 | J5: {=IFERROR(INDEX(Avg!$H$2:$H$50,MATCH(DATE(YEAR(A5),MONTH(A5),1),Avg!$A$2:$A$50,0)),"")} -> 7.9864497 | K5: {=IFERROR(INDEX(Avg!$I$2:$I$50,MATCH(DATE(YEAR(A5),MONTH(A5),1),Avg!$A$2:$A$50,0)),"")} -> 9.4622939 | L5: {=IFERROR(INDEX(Avg!$L$2:$L$50,MATCH(DATE(YEAR(A5),MONTH(A5),1),Avg!$A$2:$A$50,0)),"")} -> 28.763061 | M5: {=IFERROR(INDEX(Avg!$M$2:$M$50,MATCH(DATE(YEAR(A5),MONTH(A5),1),Avg!$A$2:$A$50,0)),"")} -> 26.766213 | N5: {=IFERROR(INDEX(Avg!$N$2:$N$50,MATCH(DATE(YEAR(A5),MONTH(A5),1),Avg!$A$2:$A$50,0)),"")} -> 7.3844773 | O5: {=IFERROR(INDEX(Avg!$O$2:$O$50,MATCH(DATE(YEAR(A5),MONTH(A5),1),Avg!$A$2:$A$50,0)),"")} -> 8.3309527
A6: 2025-12-29 | B6: 2025-12-01 | C6: Active Group | D6: =IF(SUMPRODUCT((Data!$D$2:$D$2277=A6)*(Data!$E$2:$E$2277=C6)*(Data!$M$2:$M$2277="Vladimir Zelenskiy"))>0,SUMPRODUCT((Data!$D$2:$D$2277=A6)*(Data!$E$2:$E$2277=C6)*(Data!$M$2:$M$2277="Vladimir Zelenskiy")*IF(ISNUMBER(Data!$W$2:$W$2277),Data!$W$2:$W$2277,0))/SUMPRODUCT((Data!$D$2:$D$2277=A6)*(Data!$E$2:$E$2277=C6)*(Data!$M$2:$M$2277="Vladimir Zelenskiy")),"") -> 26.8 | E6: =IF(SUMPRODUCT((Data!$D$2:$D$2277=A6)*(Data!$E$2:$E$2277=C6)*(Data!$M$2:$M$2277="Valerii Zaluzhniy"))>0,SUMPRODUCT((Data!$D$2:$D$2277=A6)*(Data!$E$2:$E$2277=C6)*(Data!$M$2:$M$2277="Valerii Zaluzhniy")*IF(ISNUMBER(Data!$W$2:$W$2277),Data!$W$2:$W$2277,0))/SUMPRODUCT((Data!$D$2:$D$2277=A6)*(Data!$E$2:$E$2277=C6)*(Data!$M$2:$M$2277="Valerii Zaluzhniy")),"") -> 25.1 | F6: =IF(SUMPRODUCT((Data!$D$2:$D$2277=A6)*(Data!$E$2:$E$2277=C6)*(Data!$M$2:$M$2277="Kyrylo Budanov"))>0,SUMPRODUCT((Data!$D$2:$D$2277=A6)*(Data!$E$2:$E$2277=C6)*(Data!$M$2:$M$2277="Kyrylo Budanov")*IF(ISNUMBER(Data!$W$2:$W$2277),Data!$W$2:$W$2277,0))/SUMPRODUCT((Data!$D$2:$D$2277=A6)*(Data!$E$2:$E$2277=C6)*(Data!$M$2:$M$2277="Kyrylo Budanov")),"") -> 10.9 | G6: =IF(SUMPRODUCT((Data!$D$2:$D$2277=A6)*(Data!$E$2:$E$2277=C6)*(Data!$M$2:$M$2277="Pyotr Poroshenko"))>0,SUMPRODUCT((Data!$D$2:$D$2277=A6)*(Data!$E$2:$E$2277=C6)*(Data!$M$2:$M$2277="Pyotr Poroshenko")*IF(ISNUMBER(Data!$W$2:$W$2277),Data!$W$2:$W$2277,0))/SUMPRODUCT((Data!$D$2:$D$2277=A6)*(Data!$E$2:$E$2277=C6)*(Data!$M$2:$M$2277="Pyotr Poroshenko")),"") -> 9.8 | H6: {=IFERROR(INDEX(Avg!$F$2:$F$50,MATCH(DATE(YEAR(A6),MONTH(A6),1),Avg!$A$2:$A$50,0)),"")} -> 29.225304 | I6: {=IFERROR(INDEX(Avg!$G$2:$G$50,MATCH(DATE(YEAR(A6),MONTH(A6),1),Avg!$A$2:$A$50,0)),"")} -> 26.319344 | J6: {=IFERROR(INDEX(Avg!$H$2:$H$50,MATCH(DATE(YEAR(A6),MONTH(A6),1),Avg!$A$2:$A$50,0)),"")} -> 7.2415013 | K6: {=IFERROR(INDEX(Avg!$I$2:$I$50,MATCH(DATE(YEAR(A6),MONTH(A6),1),Avg!$A$2:$A$50,0)),"")} -> 7.3484908 | L6: {=IFERROR(INDEX(Avg!$L$2:$L$50,MATCH(DATE(YEAR(A6),MONTH(A6),1),Avg!$A$2:$A$50,0)),"")} -> 30.34064 | M6: {=IFERROR(INDEX(Avg!$M$2:$M$50,MATCH(DATE(YEAR(A6),MONTH(A6),1),Avg!$A$2:$A$50,0)),"")} -> 26.568873 | N6: {=IFERROR(INDEX(Avg!$N$2:$N$50,MATCH(DATE(YEAR(A6),MONTH(A6),1),Avg!$A$2:$A$50,0)),"")} -> 6.6296059 | O6: {=IFERROR(INDEX(Avg!$O$2:$O$50,MATCH(DATE(YEAR(A6),MONTH(A6),1),Avg!$A$2:$A$50,0)),"")} -> 7.1756943
A7: 2026-01-14 | B7: 2025-12-01 | C7: Info Sapiens | D7: =IF(SUMPRODUCT((Data!$D$2:$D$2277=A7)*(Data!$E$2:$E$2277=C7)*(Data!$M$2:$M$2277="Vladimir Zelenskiy"))>0,SUMPRODUCT((Data!$D$2:$D$2277=A7)*(Data!$E$2:$E$2277=C7)*(Data!$M$2:$M$2277="Vladimir Zelenskiy")*IF(ISNUMBER(Data!$W$2:$W$2277),Data!$W$2:$W$2277,0))/SUMPRODUCT((Data!$D$2:$D$2277=A7)*(Data!$E$2:$E$2277=C7)*(Data!$M$2:$M$2277="Vladimir Zelenskiy")),"") -> 30.641026 | E7: =IF(SUMPRODUCT((Data!$D$2:$D$2277=A7)*(Data!$E$2:$E$2277=C7)*(Data!$M$2:$M$2277="Valerii Zaluzhniy"))>0,SUMPRODUCT((Data!$D$2:$D$2277=A7)*(Data!$E$2:$E$2277=C7)*(Data!$M$2:$M$2277="Valerii Zaluzhniy")*IF(ISNUMBER(Data!$W$2:$W$2277),Data!$W$2:$W$2277,0))/SUMPRODUCT((Data!$D$2:$D$2277=A7)*(Data!$E$2:$E$2277=C7)*(Data!$M$2:$M$2277="Valerii Zaluzhniy")),"") -> 21.923077 | F7: =IF(SUMPRODUCT((Data!$D$2:$D$2277=A7)*(Data!$E$2:$E$2277=C7)*(Data!$M$2:$M$2277="Kyrylo Budanov"))>0,SUMPRODUCT((Data!$D$2:$D$2277=A7)*(Data!$E$2:$E$2277=C7)*(Data!$M$2:$M$2277="Kyrylo Budanov")*IF(ISNUMBER(Data!$W$2:$W$2277),Data!$W$2:$W$2277,0))/SUMPRODUCT((Data!$D$2:$D$2277=A7)*(Data!$E$2:$E$2277=C7)*(Data!$M$2:$M$2277="Kyrylo Budanov")),"") -> 5.3846154 | G7: =IF(SUMPRODUCT((Data!$D$2:$D$2277=A7)*(Data!$E$2:$E$2277=C7)*(Data!$M$2:$M$2277="Pyotr Poroshenko"))>0,SUMPRODUCT((Data!$D$2:$D$2277=A7)*(Data!$E$2:$E$2277=C7)*(Data!$M$2:$M$2277="Pyotr Poroshenko")*IF(ISNUMBER(Data!$W$2:$W$2277),Data!$W$2:$W$2277,0))/SUMPRODUCT((Data!$D$2:$D$2277=A7)*(Data!$E$2:$E$2277=C7)*(Data!$M$2:$M$2277="Pyotr Poroshenko")),"") -> 5.5128205 | H7: {=IFERROR(INDEX(Avg!$F$2:$F$50,MATCH(DATE(YEAR(A7),MONTH(A7),1),Avg!$A$2:$A$50,0)),"")} -> 27.637642 | I7: {=IFERROR(INDEX(Avg!$G$2:$G$50,MATCH(DATE(YEAR(A7),MONTH(A7),1),Avg!$A$2:$A$50,0)),"")} -> 27.170279 | J7: {=IFERROR(INDEX(Avg!$H$2:$H$50,MATCH(DATE(YEAR(A7),MONTH(A7),1),Avg!$A$2:$A$50,0)),"")} -> 7.9864497 | K7: {=IFERROR(INDEX(Avg!$I$2:$I$50,MATCH(DATE(YEAR(A7),MONTH(A7),1),Avg!$A$2:$A$50,0)),"")} -> 9.4622939 | L7: {=IFERROR(INDEX(Avg!$L$2:$L$50,MATCH(DATE(YEAR(A7),MONTH(A7),1),Avg!$A$2:$A$50,0)),"")} -> 28.763061 | M7: {=IFERROR(INDEX(Avg!$M$2:$M$50,MATCH(DATE(YEAR(A7),MONTH(A7),1),Avg!$A$2:$A$50,0)),"")} -> 26.766213 | N7: {=IFERROR(INDEX(Avg!$N$2:$N$50,MATCH(DATE(YEAR(A7),MONTH(A7),1),Avg!$A$2:$A$50,0)),"")} -> 7.3844773 | O7: {=IFERROR(INDEX(Avg!$O$2:$O$50,MATCH(DATE(YEAR(A7),MONTH(A7),1),Avg!$A$2:$A$50,0)),"")} -> 8.3309527
A8: 2025-12-25 | B8: 2025-12-01 | C8: SOCIS | D8: =IF(SUMPRODUCT((Data!$D$2:$D$2277=A8)*(Data!$E$2:$E$2277=C8)*(Data!$M$2:$M$2277="Vladimir Zelenskiy"))>0,SUMPRODUCT((Data!$D$2:$D$2277=A8)*(Data!$E$2:$E$2277=C8)*(Data!$M$2:$M$2277="Vladimir Zelenskiy")*IF(ISNUMBER(Data!$W$2:$W$2277),Data!$W$2:$W$2277,0))/SUMPRODUCT((Data!$D$2:$D$2277=A8)*(Data!$E$2:$E$2277=C8)*(Data!$M$2:$M$2277="Vladimir Zelenskiy")),"") -> 30.6 | E8: =IF(SUMPRODUCT((Data!$D$2:$D$2277=A8)*(Data!$E$2:$E$2277=C8)*(Data!$M$2:$M$2277="Valerii Zaluzhniy"))>0,SUMPRODUCT((Data!$D$2:$D$2277=A8)*(Data!$E$2:$E$2277=C8)*(Data!$M$2:$M$2277="Valerii Zaluzhniy")*IF(ISNUMBER(Data!$W$2:$W$2277),Data!$W$2:$W$2277,0))/SUMPRODUCT((Data!$D$2:$D$2277=A8)*(Data!$E$2:$E$2277=C8)*(Data!$M$2:$M$2277="Valerii Zaluzhniy")),"") -> 29.6 | F8: =IF(SUMPRODUCT((Data!$D$2:$D$2277=A8)*(Data!$E$2:$E$2277=C8)*(Data!$M$2:$M$2277="Kyrylo Budanov"))>0,SUMPRODUCT((Data!$D$2:$D$2277=A8)*(Data!$E$2:$E$2277=C8)*(Data!$M$2:$M$2277="Kyrylo Budanov")*IF(ISNUMBER(Data!$W$2:$W$2277),Data!$W$2:$W$2277,0))/SUMPRODUCT((Data!$D$2:$D$2277=A8)*(Data!$E$2:$E$2277=C8)*(Data!$M$2:$M$2277="Kyrylo Budanov")),"") -> 8.1 | G8: =IF(SUMPRODUCT((Data!$D$2:$D$2277=A8)*(Data!$E$2:$E$2277=C8)*(Data!$M$2:$M$2277="Pyotr Poroshenko"))>0,SUMPRODUCT((Data!$D$2:$D$2277=A8)*(Data!$E$2:$E$2277=C8)*(Data!$M$2:$M$2277="Pyotr Poroshenko")*IF(ISNUMBER(Data!$W$2:$W$2277),Data!$W$2:$W$2277,0))/SUMPRODUCT((Data!$D$2:$D$2277=A8)*(Data!$E$2:$E$2277=C8)*(Data!$M$2:$M$2277="Pyotr Poroshenko")),"") -> 7.2 | H8: {=IFERROR(INDEX(Avg!$F$2:$F$50,MATCH(DATE(YEAR(A8),MONTH(A8),1),Avg!$A$2:$A$50,0)),"")} -> 29.225304 | I8: {=IFERROR(INDEX(Avg!$G$2:$G$50,MATCH(DATE(YEAR(A8),MONTH(A8),1),Avg!$A$2:$A$50,0)),"")} -> 26.319344 | J8: {=IFERROR(INDEX(Avg!$H$2:$H$50,MATCH(DATE(YEAR(A8),MONTH(A8),1),Avg!$A$2:$A$50,0)),"")} -> 7.2415013 | K8: {=IFERROR(INDEX(Avg!$I$2:$I$50,MATCH(DATE(YEAR(A8),MONTH(A8),1),Avg!$A$2:$A$50,0)),"")} -> 7.3484908 | L8: {=IFERROR(INDEX(Avg!$L$2:$L$50,MATCH(DATE(YEAR(A8),MONTH(A8),1),Avg!$A$2:$A$50,0)),"")} -> 30.34064 | M8: {=IFERROR(INDEX(Avg!$M$2:$M$50,MATCH(DATE(YEAR(A8),MONTH(A8),1),Avg!$A$2:$A$50,0)),"")} -> 26.568873 | N8: {=IFERROR(INDEX(Avg!$N$2:$N$50,MATCH(DATE(YEAR(A8),MONTH(A8),1),Avg!$A$2:$A$50,0)),"")} -> 6.6296059 | O8: {=IFERROR(INDEX(Avg!$O$2:$O$50,MATCH(DATE(YEAR(A8),MONTH(A8),1),Avg!$A$2:$A$50,0)),"")} -> 7.1756943
A9: 2025-12-13 | B9: 2025-12-01 | C9: NewImage commissioned by Business capital | D9: =IF(SUMPRODUCT((Data!$D$2:$D$2277=A9)*(Data!$E$2:$E$2277=C9)*(Data!$M$2:$M$2277="Vladimir Zelenskiy"))>0,SUMPRODUCT((Data!$D$2:$D$2277=A9)*(Data!$E$2:$E$2277=C9)*(Data!$M$2:$M$2277="Vladimir Zelenskiy")*IF(ISNUMBER(Data!$W$2:$W$2277),Data!$W$2:$W$2277,0))/SUMPRODUCT((Data!$D$2:$D$2277=A9)*(Data!$E$2:$E$2277=C9)*(Data!$M$2:$M$2277="Vladimir Zelenskiy")),"") -> 33.4 | E9: =IF(SUMPRODUCT((Data!$D$2:$D$2277=A9)*(Data!$E$2:$E$2277=C9)*(Data!$M$2:$M$2277="Valerii Zaluzhniy"))>0,SUMPRODUCT((Data!$D$2:$D$2277=A9)*(Data!$E$2:$E$2277=C9)*(Data!$M$2:$M$2277="Valerii Zaluzhniy")*IF(ISNUMBER(Data!$W$2:$W$2277),Data!$W$2:$W$2277,0))/SUMPRODUCT((Data!$D$2:$D$2277=A9)*(Data!$E$2:$E$2277=C9)*(Data!$M$2:$M$2277="Valerii Zaluzhniy")),"") -> 26 | F9: =IF(SUMPRODUCT((Data!$D$2:$D$2277=A9)*(Data!$E$2:$E$2277=C9)*(Data!$M$2:$M$2277="Kyrylo Budanov"))>0,SUMPRODUCT((Data!$D$2:$D$2277=A9)*(Data!$E$2:$E$2277=C9)*(Data!$M$2:$M$2277="Kyrylo Budanov")*IF(ISNUMBER(Data!$W$2:$W$2277),Data!$W$2:$W$2277,0))/SUMPRODUCT((Data!$D$2:$D$2277=A9)*(Data!$E$2:$E$2277=C9)*(Data!$M$2:$M$2277="Kyrylo Budanov")),"") -> 4.8 | G9: =IF(SUMPRODUCT((Data!$D$2:$D$2277=A9)*(Data!$E$2:$E$2277=C9)*(Data!$M$2:$M$2277="Pyotr Poroshenko"))>0,SUMPRODUCT((Data!$D$2:$D$2277=A9)*(Data!$E$2:$E$2277=C9)*(Data!$M$2:$M$2277="Pyotr Poroshenko")*IF(ISNUMBER(Data!$W$2:$W$2277),Data!$W$2:$W$2277,0))/SUMPRODUCT((Data!$D$2:$D$2277=A9)*(Data!$E$2:$E$2277=C9)*(Data!$M$2:$M$2277="Pyotr Poroshenko")),"") -> 9.2 | H9: {=IFERROR(INDEX(Avg!$F$2:$F$50,MATCH(DATE(YEAR(A9),MONTH(A9),1),Avg!$A$2:$A$50,0)),"")} -> 29.225304 | I9: {=IFERROR(INDEX(Avg!$G$2:$G$50,MATCH(DATE(YEAR(A9),MONTH(A9),1),Avg!$A$2:$A$50,0)),"")} -> 26.319344 | J9: {=IFERROR(INDEX(Avg!$H$2:$H$50,MATCH(DATE(YEAR(A9),MONTH(A9),1),Avg!$A$2:$A$50,0)),"")} -> 7.2415013 | K9: {=IFERROR(INDEX(Avg!$I$2:$I$50,MATCH(DATE(YEAR(A9),MONTH(A9),1),Avg!$A$2:$A$50,0)),"")} -> 7.3484908 | L9: {=IFERROR(INDEX(Avg!$L$2:$L$50,MATCH(DATE(YEAR(A9),MONTH(A9),1),Avg!$A$2:$A$50,0)),"")} -> 30.34064 | M9: {=IFERROR(INDEX(Avg!$M$2:$M$50,MATCH(DATE(YEAR(A9),MONTH(A9),1),Avg!$A$2:$A$50,0)),"")} -> 26.568873 | N9: {=IFERROR(INDEX(Avg!$N$2:$N$50,MATCH(DATE(YEAR(A9),MONTH(A9),1),Avg!$A$2:$A$50,0)),"")} -> 6.6296059 | O9: {=IFERROR(INDEX(Avg!$O$2:$O$50,MATCH(DATE(YEAR(A9),MONTH(A9),1),Avg!$A$2:$A$50,0)),"")} -> 7.1756943
A10: 2025-12-09 | B10: 2025-11-01 | C10: Info Sapiens | D10: =IF(SUMPRODUCT((Data!$D$2:$D$2277=A10)*(Data!$E$2:$E$2277=C10)*(Data!$M$2:$M$2277="Vladimir Zelenskiy"))>0,SUMPRODUCT((Data!$D$2:$D$2277=A10)*(Data!$E$2:$E$2277=C10)*(Data!$M$2:$M$2277="Vladimir Zelenskiy")*IF(ISNUMBER(Data!$W$2:$W$2277),Data!$W$2:$W$2277,0))/SUMPRODUCT((Data!$D$2:$D$2277=A10)*(Data!$E$2:$E$2277=C10)*(Data!$M$2:$M$2277="Vladimir Zelenskiy")),"") -> 26.025641 | E10: =IF(SUMPRODUCT((Data!$D$2:$D$2277=A10)*(Data!$E$2:$E$2277=C10)*(Data!$M$2:$M$2277="Valerii Zaluzhniy"))>0,SUMPRODUCT((Data!$D$2:$D$2277=A10)*(Data!$E$2:$E$2277=C10)*(Data!$M$2:$M$2277="Valerii Zaluzhniy")*IF(ISNUMBER(Data!$W$2:$W$2277),Data!$W$2:$W$2277,0))/SUMPRODUCT((Data!$D$2:$D$2277=A10)*(Data!$E$2:$E$2277=C10)*(Data!$M$2:$M$2277="Valerii Zaluzhniy")),"") -> 24.487179 | F10: =IF(SUMPRODUCT((Data!$D$2:$D$2277=A10)*(Data!$E$2:$E$2277=C10)*(Data!$M$2:$M$2277="Kyrylo Budanov"))>0,SUMPRODUCT((Data!$D$2:$D$2277=A10)*(Data!$E$2:$E$2277=C10)*(Data!$M$2:$M$2277="Kyrylo Budanov")*IF(ISNUMBER(Data!$W$2:$W$2277),Data!$W$2:$W$2277,0))/SUMPRODUCT((Data!$D$2:$D$2277=A10)*(Data!$E$2:$E$2277=C10)*(Data!$M$2:$M$2277="Kyrylo Budanov")),"") -> 6.5384615 | G10: =IF(SUMPRODUCT((Data!$D$2:$D$2277=A10)*(Data!$E$2:$E$2277=C10)*(Data!$M$2:$M$2277="Pyotr Poroshenko"))>0,SUMPRODUCT((Data!$D$2:$D$2277=A10)*(Data!$E$2:$E$2277=C10)*(Data!$M$2:$M$2277="Pyotr Poroshenko")*IF(ISNUMBER(Data!$W$2:$W$2277),Data!$W$2:$W$2277,0))/SUMPRODUCT((Data!$D$2:$D$2277=A10)*(Data!$E$2:$E$2277=C10)*(Data!$M$2:$M$2277="Pyotr Poroshenko")),"") -> 5.8974359 | H10: {=IFERROR(INDEX(Avg!$F$2:$F$50,MATCH(DATE(YEAR(A10),MONTH(A10),1),Avg!$A$2:$A$50,0)),"")} -> 29.225304 | I10: {=IFERROR(INDEX(Avg!$G$2:$G$50,MATCH(DATE(YEAR(A10),MONTH(A10),1),Avg!$A$2:$A$50,0)),"")} -> 26.319344 | J10: {=IFERROR(INDEX(Avg!$H$2:$H$50,MATCH(DATE(YEAR(A10),MONTH(A10),1),Avg!$A$2:$A$50,0)),"")} -> 7.2415013 | K10: {=IFERROR(INDEX(Avg!$I$2:$I$50,MATCH(DATE(YEAR(A10),MONTH(A10),1),Avg!$A$2:$A$50,0)),"")} -> 7.3484908 | L10: {=IFERROR(INDEX(Avg!$L$2:$L$50,MATCH(DATE(YEAR(A10),MONTH(A10),1),Avg!$A$2:$A$50,0)),"")} -> 30.34064 | M10: {=IFERROR(INDEX(Avg!$M$2:$M$50,MATCH(DATE(YEAR(A10),MONTH(A10),1),Avg!$A$2:$A$50,0)),"")} -> 26.568873 | N10: {=IFERROR(INDEX(Avg!$N$2:$N$50,MATCH(DATE(YEAR(A10),MONTH(A10),1),Avg!$A$2:$A$50,0)),"")} -> 6.6296059 | O10: {=IFERROR(INDEX(Avg!$O$2:$O$50,MATCH(DATE(YEAR(A10),MONTH(A10),1),Avg!$A$2:$A$50,0)),"")} -> 7.1756943
A11: 2025-11-01 | B11: 2025-10-01 | C11: Info Sapiens | D11: =IF(SUMPRODUCT((Data!$D$2:$D$2277=A11)*(Data!$E$2:$E$2277=C11)*(Data!$M$2:$M$2277="Vladimir Zelenskiy"))>0,SUMPRODUCT((Data!$D$2:$D$2277=A11)*(Data!$E$2:$E$2277=C11)*(Data!$M$2:$M$2277="Vladimir Zelenskiy")*IF(ISNUMBER(Data!$W$2:$W$2277),Data!$W$2:$W$2277,0))/SUMPRODUCT((Data!$D$2:$D$2277=A11)*(Data!$E$2:$E$2277=C11)*(Data!$M$2:$M$2277="Vladimir Zelenskiy")),"") -> 31.153846 | E11: =IF(SUMPRODUCT((Data!$D$2:$D$2277=A11)*(Data!$E$2:$E$2277=C11)*(Data!$M$2:$M$2277="Valerii Zaluzhniy"))>0,SUMPRODUCT((Data!$D$2:$D$2277=A11)*(Data!$E$2:$E$2277=C11)*(Data!$M$2:$M$2277="Valerii Zaluzhniy")*IF(ISNUMBER(Data!$W$2:$W$2277),Data!$W$2:$W$2277,0))/SUMPRODUCT((Data!$D$2:$D$2277=A11)*(Data!$E$2:$E$2277=C11)*(Data!$M$2:$M$2277="Valerii Zaluzhniy")),"") -> 21.025641 | F11: =IF(SUMPRODUCT((Data!$D$2:$D$2277=A11)*(Data!$E$2:$E$2277=C11)*(Data!$M$2:$M$2277="Kyrylo Budanov"))>0,SUMPRODUCT((Data!$D$2:$D$2277=A11)*(Data!$E$2:$E$2277=C11)*(Data!$M$2:$M$2277="Kyrylo Budanov")*IF(ISNUMBER(Data!$W$2:$W$2277),Data!$W$2:$W$2277,0))/SUMPRODUCT((Data!$D$2:$D$2277=A11)*(Data!$E$2:$E$2277=C11)*(Data!$M$2:$M$2277="Kyrylo Budanov")),"") -> 6.025641 | G11: =IF(SUMPRODUCT((Data!$D$2:$D$2277=A11)*(Data!$E$2:$E$2277=C11)*(Data!$M$2:$M$2277="Pyotr Poroshenko"))>0,SUMPRODUCT((Data!$D$2:$D$2277=A11)*(Data!$E$2:$E$2277=C11)*(Data!$M$2:$M$2277="Pyotr Poroshenko")*IF(ISNUMBER(Data!$W$2:$W$2277),Data!$W$2:$W$2277,0))/SUMPRODUCT((Data!$D$2:$D$2277=A11)*(Data!$E$2:$E$2277=C11)*(Data!$M$2:$M$2277="Pyotr Poroshenko")),"") -> 5.8974359 | H11: {=IFERROR(INDEX(Avg!$F$2:$F$50,MATCH(DATE(YEAR(A11),MONTH(A11),1),Avg!$A$2:$A$50,0)),"")} -> 31.214833 | I11: {=IFERROR(INDEX(Avg!$G$2:$G$50,MATCH(DATE(YEAR(A11),MONTH(A11),1),Avg!$A$2:$A$50,0)),"")} -> 26.447754 | J11: {=IFERROR(INDEX(Avg!$H$2:$H$50,MATCH(DATE(YEAR(A11),MONTH(A11),1),Avg!$A$2:$A$50,0)),"")} -> 5.8645122 | K11: {=IFERROR(INDEX(Avg!$I$2:$I$50,MATCH(DATE(YEAR(A11),MONTH(A11),1),Avg!$A$2:$A$50,0)),"")} -> 6.9018531 | L11: {=IFERROR(INDEX(Avg!$L$2:$L$50,MATCH(DATE(YEAR(A11),MONTH(A11),1),Avg!$A$2:$A$50,0)),"")} -> 32.560707 | M11: {=IFERROR(INDEX(Avg!$M$2:$M$50,MATCH(DATE(YEAR(A11),MONTH(A11),1),Avg!$A$2:$A$50,0)),"")} -> 27.482469 | N11: {=IFERROR(INDEX(Avg!$N$2:$N$50,MATCH(DATE(YEAR(A11),MONTH(A11),1),Avg!$A$2:$A$50,0)),"")} -> 5.9462867 | O11: {=IFERROR(INDEX(Avg!$O$2:$O$50,MATCH(DATE(YEAR(A11),MONTH(A11),1),Avg!$A$2:$A$50,0)),"")} -> 7.0419983
A12: 2025-11-21 | B12: 2025-10-01 | C12: SOCIS | D12: =IF(SUMPRODUCT((Data!$D$2:$D$2277=A12)*(Data!$E$2:$E$2277=C12)*(Data!$M$2:$M$2277="Vladimir Zelenskiy"))>0,SUMPRODUCT((Data!$D$2:$D$2277=A12)*(Data!$E$2:$E$2277=C12)*(Data!$M$2:$M$2277="Vladimir Zelenskiy")*IF(ISNUMBER(Data!$W$2:$W$2277),Data!$W$2:$W$2277,0))/SUMPRODUCT((Data!$D$2:$D$2277=A12)*(Data!$E$2:$E$2277=C12)*(Data!$M$2:$M$2277="Vladimir Zelenskiy")),"") -> 30.1 | E12: =IF(SUMPRODUCT((Data!$D$2:$D$2277=A12)*(Data!$E$2:$E$2277=C12)*(Data!$M$2:$M$2277="Valerii Zaluzhniy"))>0,SUMPRODUCT((Data!$D$2:$D$2277=A12)*(Data!$E$2:$E$2277=C12)*(Data!$M$2:$M$2277="Valerii Zaluzhniy")*IF(ISNUMBER(Data!$W$2:$W$2277),Data!$W$2:$W$2277,0))/SUMPRODUCT((Data!$D$2:$D$2277=A12)*(Data!$E$2:$E$2277=C12)*(Data!$M$2:$M$2277="Valerii Zaluzhniy")),"") -> 28.9 | F12: =IF(SUMPRODUCT((Data!$D$2:$D$2277=A12)*(Data!$E$2:$E$2277=C12)*(Data!$M$2:$M$2277="Kyrylo Budanov"))>0,SUMPRODUCT((Data!$D$2:$D$2277=A12)*(Data!$E$2:$E$2277=C12)*(Data!$M$2:$M$2277="Kyrylo Budanov")*IF(ISNUMBER(Data!$W$2:$W$2277),Data!$W$2:$W$2277,0))/SUMPRODUCT((Data!$D$2:$D$2277=A12)*(Data!$E$2:$E$2277=C12)*(Data!$M$2:$M$2277="Kyrylo Budanov")),"") -> 5 | G12: =IF(SUMPRODUCT((Data!$D$2:$D$2277=A12)*(Data!$E$2:$E$2277=C12)*(Data!$M$2:$M$2277="Pyotr Poroshenko"))>0,SUMPRODUCT((Data!$D$2:$D$2277=A12)*(Data!$E$2:$E$2277=C12)*(Data!$M$2:$M$2277="Pyotr Poroshenko")*IF(ISNUMBER(Data!$W$2:$W$2277),Data!$W$2:$W$2277,0))/SUMPRODUCT((Data!$D$2:$D$2277=A12)*(Data!$E$2:$E$2277=C12)*(Data!$M$2:$M$2277="Pyotr Poroshenko")),"") -> 7.2 | H12: {=IFERROR(INDEX(Avg!$F$2:$F$50,MATCH(DATE(YEAR(A12),MONTH(A12),1),Avg!$A$2:$A$50,0)),"")} -> 31.214833 | I12: {=IFERROR(INDEX(Avg!$G$2:$G$50,MATCH(DATE(YEAR(A12),MONTH(A12),1),Avg!$A$2:$A$50,0)),"")} -> 26.447754 | J12: {=IFERROR(INDEX(Avg!$H$2:$H$50,MATCH(DATE(YEAR(A12),MONTH(A12),1),Avg!$A$2:$A$50,0)),"")} -> 5.8645122 | K12: {=IFERROR(INDEX(Avg!$I$2:$I$50,MATCH(DATE(YEAR(A12),MONTH(A12),1),Avg!$A$2:$A$50,0)),"")} -> 6.9018531 | L12: {=IFERROR(INDEX(Avg!$L$2:$L$50,MATCH(DATE(YEAR(A12),MONTH(A12),1),Avg!$A$2:$A$50,0)),"")} -> 32.560707 | M12: {=IFERROR(INDEX(Avg!$M$2:$M$50,MATCH(DATE(YEAR(A12),MONTH(A12),1),Avg!$A$2:$A$50,0)),"")} -> 27.482469 | N12: {=IFERROR(INDEX(Avg!$N$2:$N$50,MATCH(DATE(YEAR(A12),MONTH(A12),1),Avg!$A$2:$A$50,0)),"")} -> 5.9462867 | O12: {=IFERROR(INDEX(Avg!$O$2:$O$50,MATCH(DATE(YEAR(A12),MONTH(A12),1),Avg!$A$2:$A$50,0)),"")} -> 7.0419983
A13: 2025-10-13 | B13: 2025-10-01 | C13: Rate 1 research commissioned by American Political Services, LLC | D13: =IF(SUMPRODUCT((Data!$D$2:$D$2277=A13)*(Data!$E$2:$E$2277=C13)*(Data!$M$2:$M$2277="Vladimir Zelenskiy"))>0,SUMPRODUCT((Data!$D$2:$D$2277=A13)*(Data!$E$2:$E$2277=C13)*(Data!$M$2:$M$2277="Vladimir Zelenskiy")*IF(ISNUMBER(Data!$W$2:$W$2277),Data!$W$2:$W$2277,0))/SUMPRODUCT((Data!$D$2:$D$2277=A13)*(Data!$E$2:$E$2277=C13)*(Data!$M$2:$M$2277="Vladimir Zelenskiy")),"") -> 30.3 | E13: =IF(SUMPRODUCT((Data!$D$2:$D$2277=A13)*(Data!$E$2:$E$2277=C13)*(Data!$M$2:$M$2277="Valerii Zaluzhniy"))>0,SUMPRODUCT((Data!$D$2:$D$2277=A13)*(Data!$E$2:$E$2277=C13)*(Data!$M$2:$M$2277="Valerii Zaluzhniy")*IF(ISNUMBER(Data!$W$2:$W$2277),Data!$W$2:$W$2277,0))/SUMPRODUCT((Data!$D$2:$D$2277=A13)*(Data!$E$2:$E$2277=C13)*(Data!$M$2:$M$2277="Valerii Zaluzhniy")),"") -> 28.5 | F13: =IF(SUMPRODUCT((Data!$D$2:$D$2277=A13)*(Data!$E$2:$E$2277=C13)*(Data!$M$2:$M$2277="Kyrylo Budanov"))>0,SUMPRODUCT((Data!$D$2:$D$2277=A13)*(Data!$E$2:$E$2277=C13)*(Data!$M$2:$M$2277="Kyrylo Budanov")*IF(ISNUMBER(Data!$W$2:$W$2277),Data!$W$2:$W$2277,0))/SUMPRODUCT((Data!$D$2:$D$2277=A13)*(Data!$E$2:$E$2277=C13)*(Data!$M$2:$M$2277="Kyrylo Budanov")),"") -> 10.1 | G13: =IF(SUMPRODUCT((Data!$D$2:$D$2277=A13)*(Data!$E$2:$E$2277=C13)*(Data!$M$2:$M$2277="Pyotr Poroshenko"))>0,SUMPRODUCT((Data!$D$2:$D$2277=A13)*(Data!$E$2:$E$2277=C13)*(Data!$M$2:$M$2277="Pyotr Poroshenko")*IF(ISNUMBER(Data!$W$2:$W$2277),Data!$W$2:$W$2277,0))/SUMPRODUCT((Data!$D$2:$D$2277=A13)*(Data!$E$2:$E$2277=C13)*(Data!$M$2:$M$2277="Pyotr Poroshenko")),"") -> 7.6 | H13: {=IFERROR(INDEX(Avg!$F$2:$F$50,MATCH(DATE(YEAR(A13),MONTH(A13),1),Avg!$A$2:$A$50,0)),"")} -> 31.938266 | I13: {=IFERROR(INDEX(Avg!$G$2:$G$50,MATCH(DATE(YEAR(A13),MONTH(A13),1),Avg!$A$2:$A$50,0)),"")} -> 27.559697 | J13: {=IFERROR(INDEX(Avg!$H$2:$H$50,MATCH(DATE(YEAR(A13),MONTH(A13),1),Avg!$A$2:$A$50,0)),"")} -> 6.3241068 | K13: {=IFERROR(INDEX(Avg!$I$2:$I$50,MATCH(DATE(YEAR(A13),MONTH(A13),1),Avg!$A$2:$A$50,0)),"")} -> 7.2049874 | L13: {=IFERROR(INDEX(Avg!$L$2:$L$50,MATCH(DATE(YEAR(A13),MONTH(A13),1),Avg!$A$2:$A$50,0)),"")} -> 34.890738 | M13: {=IFERROR(INDEX(Avg!$M$2:$M$50,MATCH(DATE(YEAR(A13),MONTH(A13),1),Avg!$A$2:$A$50,0)),"")} -> 28.995927 | N13: {=IFERROR(INDEX(Avg!$N$2:$N$50,MATCH(DATE(YEAR(A13),MONTH(A13),1),Avg!$A$2:$A$50,0)),"")} -> 5.8800383 | O13: {=IFERROR(INDEX(Avg!$O$2:$O$50,MATCH(DATE(YEAR(A13),MONTH(A13),1),Avg!$A$2:$A$50,0)),"")} -> 7.1707217
... A207: 2019-04-01 | B207: 2019-03-01 | C207: OPORA | D207: =IF(SUMPRODUCT((Data!$D$2:$D$2277=A207)*(Data!$E$2:$E$2277=C207)*(Data!$M$2:$M$2277="Vladimir Zelenskiy"))>0,SUMPRODUCT((Data!$D$2:$D$2277=A207)*(Data!$E$2:$E$2277=C207)*(Data!$M$2:$M$2277="Vladimir Zelenskiy")*IF(ISNUMBER(Data!$W$2:$W$2277),Data!$W$2:$W$2277,0))/SUMPRODUCT((Data!$D$2:$D$2277=A207)*(Data!$E$2:$E$2277=C207)*(Data!$M$2:$M$2277="Vladimir Zelenskiy")),"") -> 30.1 | E207: =IF(SUMPRODUCT((Data!$D$2:$D$2277=A207)*(Data!$E$2:$E$2277=C207)*(Data!$M$2:$M$2277="Valerii Zaluzhniy"))>0,SUMPRODUCT((Data!$D$2:$D$2277=A207)*(Data!$E$2:$E$2277=C207)*(Data!$M$2:$M$2277="Valerii Zaluzhniy")*IF(ISNUMBER(Data!$W$2:$W$2277),Data!$W$2:$W$2277,0))/SUMPRODUCT((Data!$D$2:$D$2277=A207)*(Data!$E$2:$E$2277=C207)*(Data!$M$2:$M$2277="Valerii Zaluzhniy")),"") | F207: =IF(SUMPRODUCT((Data!$D$2:$D$2277=A207)*(Data!$E$2:$E$2277=C207)*(Data!$M$2:$M$2277="Kyrylo Budanov"))>0,SUMPRODUCT((Data!$D$2:$D$2277=A207)*(Data!$E$2:$E$2277=C207)*(Data!$M$2:$M$2277="Kyrylo Budanov")*IF(ISNUMBER(Data!$W$2:$W$2277),Data!$W$2:$W$2277,0))/SUMPRODUCT((Data!$D$2:$D$2277=A207)*(Data!$E$2:$E$2277=C207)*(Data!$M$2:$M$2277="Kyrylo Budanov")),"") | G207: =IF(SUMPRODUCT((Data!$D$2:$D$2277=A207)*(Data!$E$2:$E$2277=C207)*(Data!$M$2:$M$2277="Pyotr Poroshenko"))>0,SUMPRODUCT((Data!$D$2:$D$2277=A207)*(Data!$E$2:$E$2277=C207)*(Data!$M$2:$M$2277="Pyotr Poroshenko")*IF(ISNUMBER(Data!$W$2:$W$2277),Data!$W$2:$W$2277,0))/SUMPRODUCT((Data!$D$2:$D$2277=A207)*(Data!$E$2:$E$2277=C207)*(Data!$M$2:$M$2277="Pyotr Poroshenko")),"") -> 15.7 | H207: {=IFERROR(INDEX(Avg!$F$2:$F$50,MATCH(DATE(YEAR(A207),MONTH(A207),1),Avg!$A$2:$A$50,0)),"")} | I207: {=IFERROR(INDEX(Avg!$G$2:$G$50,MATCH(DATE(YEAR(A207),MONTH(A207),1),Avg!$A$2:$A$50,0)),"")} | J207: {=IFERROR(INDEX(Avg!$H$2:$H$50,MATCH(DATE(YEAR(A207),MONTH(A207),1),Avg!$A$2:$A$50,0)),"")} | K207: {=IFERROR(INDEX(Avg!$I$2:$I$50,MATCH(DATE(YEAR(A207),MONTH(A207),1),Avg!$A$2:$A$50,0)),"")} | L207: {=IFERROR(INDEX(Avg!$L$2:$L$50,MATCH(DATE(YEAR(A207),MONTH(A207),1),Avg!$A$2:$A$50,0)),"")} | M207: {=IFERROR(INDEX(Avg!$M$2:$M$50,MATCH(DATE(YEAR(A207),MONTH(A207),1),Avg!$A$2:$A$50,0)),"")} | N207: {=IFERROR(INDEX(Avg!$N$2:$N$50,MATCH(DATE(YEAR(A207),MONTH(A207),1),Avg!$A$2:$A$50,0)),"")} | O207: {=IFERROR(INDEX(Avg!$O$2:$O$50,MATCH(DATE(YEAR(A207),MONTH(A207),1),Avg!$A$2:$A$50,0)),"")}

Sheet Data
A1: row_id | B1: poll_id | C1: poll_url | D1: publication_date | E1: pollster | F1: poll_region | G1: time_frame_start | H1: time_frame_end | I1: number_of_respondents | J1: sampling_error_pct | K1: polling_method | L1: rating_scope | M1: candidate | N1: percent | O1: year_month | P1: method_weight | Q1: precision_weight | R1: obs_weight | S1: recency_weight | T1: flood_weight | U1: final_weight | V1: scope_factor | W1: normalised_percent
A2: 2241:Vladimir Zelenskiy | B2: 2241 | C2: https://ukraine-elections.com.ua/en/socopros/opinion_poll_show/2241 | D2: 2026-03-26 | E2: SOCIS | F2: Ukraine | G2: 2026-03-12 | H2: 2026-03-18 | I2: 1204 | J2: 2.5 | K2: CATI - computer-assisted telephone interviews | L2: Among those who will vote and have made their choice | M2: Vladimir Zelenskiy | N2: 29.3 | O2: =DATE(YEAR(D2),MONTH(D2),1) -> 46082 | P2: =IFERROR(VLOOKUP(K2,Formula!$A$11:$B$20,2,FALSE),Formula!$C$26) -> 0.9 | Q2: =IF(AND(ISNUMBER(J2),J2>0),1/J2,IF(AND(ISNUMBER(I2),I2>0),SQRT(MIN(I2,Formula!$C$27))/Formula!$C$24,1/Formula!$C$25)) -> 0.4 | R2: =P2*Q2 -> 0.36 | S2: =IF(H2<>"",EXP(-Formula!$C$28*(EOMONTH(H2,0)-H2)),EXP(-Formula!$C$28*(EOMONTH(D2,0)-D2))) -> 0.52204578 | T2: =IFERROR(SQRT(1/COUNTIFS($E$2:$E$2277,E2,$O$2:$O$2277,O2)),1) -> 0.28867513 | U2: =P2*Q2*S2*T2 -> 0.054252589 | V2: =IF(AND(L2="Among all respondents",NOT(OR(K2="Online poll in Telegram channel",K2="Website online poll",K2="CAWI (Computer Assisted Web Interviewing)"))),1/(1-MIN(MAX(Formula!$C$33+(YEAR(D2)-Formula!$C$34)/(Formula!$C$35-Formula!$C$34)*(Formula!$C$32-Formula!$C$33),Formula!$C$33),Formula!$C$32)),1) -> 1 | W2: =IF(ISNUMBER(N2),N2*V2,"") -> 29.3
A3: 2241:Valerii Zaluzhniy | B3: 2241 | C3: https://ukraine-elections.com.ua/en/socopros/opinion_poll_show/2241 | D3: 2026-03-26 | E3: SOCIS | F3: Ukraine | G3: 2026-03-12 | H3: 2026-03-18 | I3: 1204 | J3: 2.5 | K3: CATI - computer-assisted telephone interviews | L3: Among those who will vote and have made their choice | M3: Valerii Zaluzhniy | N3: 25 | O3: =DATE(YEAR(D3),MONTH(D3),1) -> 46082 | P3: =IFERROR(VLOOKUP(K3,Formula!$A$11:$B$20,2,FALSE),Formula!$C$26) -> 0.9 | Q3: =IF(AND(ISNUMBER(J3),J3>0),1/J3,IF(AND(ISNUMBER(I3),I3>0),SQRT(MIN(I3,Formula!$C$27))/Formula!$C$24,1/Formula!$C$25)) -> 0.4 | R3: =P3*Q3 -> 0.36 | S3: =IF(H3<>"",EXP(-Formula!$C$28*(EOMONTH(H3,0)-H3)),EXP(-Formula!$C$28*(EOMONTH(D3,0)-D3))) -> 0.52204578 | T3: =IFERROR(SQRT(1/COUNTIFS($E$2:$E$2277,E3,$O$2:$O$2277,O3)),1) -> 0.28867513 | U3: =P3*Q3*S3*T3 -> 0.054252589 | V3: =IF(AND(L3="Among all respondents",NOT(OR(K3="Online poll in Telegram channel",K3="Website online poll",K3="CAWI (Computer Assisted Web Interviewing)"))),1/(1-MIN(MAX(Formula!$C$33+(YEAR(D3)-Formula!$C$34)/(Formula!$C$35-Formula!$C$34)*(Formula!$C$32-Formula!$C$33),Formula!$C$33),Formula!$C$32)),1) -> 1 | W3: =IF(ISNUMBER(N3),N3*V3,"") -> 25
A4: 2241:Kyrylo Budanov | B4: 2241 | C4: https://ukraine-elections.com.ua/en/socopros/opinion_poll_show/2241 | D4: 2026-03-26 | E4: SOCIS | F4: Ukraine | G4: 2026-03-12 | H4: 2026-03-18 | I4: 1204 | J4: 2.5 | K4: CATI - computer-assisted telephone interviews | L4: Among those who will vote and have made their choice | M4: Kyrylo Budanov | N4: 13.7 | O4: =DATE(YEAR(D4),MONTH(D4),1) -> 46082 | P4: =IFERROR(VLOOKUP(K4,Formula!$A$11:$B$20,2,FALSE),Formula!$C$26) -> 0.9 | Q4: =IF(AND(ISNUMBER(J4),J4>0),1/J4,IF(AND(ISNUMBER(I4),I4>0),SQRT(MIN(I4,Formula!$C$27))/Formula!$C$24,1/Formula!$C$25)) -> 0.4 | R4: =P4*Q4 -> 0.36 | S4: =IF(H4<>"",EXP(-Formula!$C$28*(EOMONTH(H4,0)-H4)),EXP(-Formula!$C$28*(EOMONTH(D4,0)-D4))) -> 0.52204578 | T4: =IFERROR(SQRT(1/COUNTIFS($E$2:$E$2277,E4,$O$2:$O$2277,O4)),1) -> 0.28867513 | U4: =P4*Q4*S4*T4 -> 0.054252589 | V4: =IF(AND(L4="Among all respondents",NOT(OR(K4="Online poll in Telegram channel",K4="Website online poll",K4="CAWI (Computer Assisted Web Interviewing)"))),1/(1-MIN(MAX(Formula!$C$33+(YEAR(D4)-Formula!$C$34)/(Formula!$C$35-Formula!$C$34)*(Formula!$C$32-Formula!$C$33),Formula!$C$33),Formula!$C$32)),1) -> 1 | W4: =IF(ISNUMBER(N4),N4*V4,"") -> 13.7
A5: 2241:Pyotr Poroshenko | B5: 2241 | C5: https://ukraine-elections.com.ua/en/socopros/opinion_poll_show/2241 | D5: 2026-03-26 | E5: SOCIS | F5: Ukraine | G5: 2026-03-12 | H5: 2026-03-18 | I5: 1204 | J5: 2.5 | K5: CATI - computer-assisted telephone interviews | L5: Among those who will vote and have made their choice | M5: Pyotr Poroshenko | N5: 7.4 | O5: =DATE(YEAR(D5),MONTH(D5),1) -> 46082 | P5: =IFERROR(VLOOKUP(K5,Formula!$A$11:$B$20,2,FALSE),Formula!$C$26) -> 0.9 | Q5: =IF(AND(ISNUMBER(J5),J5>0),1/J5,IF(AND(ISNUMBER(I5),I5>0),SQRT(MIN(I5,Formula!$C$27))/Formula!$C$24,1/Formula!$C$25)) -> 0.4 | R5: =P5*Q5 -> 0.36 | S5: =IF(H5<>"",EXP(-Formula!$C$28*(EOMONTH(H5,0)-H5)),EXP(-Formula!$C$28*(EOMONTH(D5,0)-D5))) -> 0.52204578 | T5: =IFERROR(SQRT(1/COUNTIFS($E$2:$E$2277,E5,$O$2:$O$2277,O5)),1) -> 0.28867513 | U5: =P5*Q5*S5*T5 -> 0.054252589 | V5: =IF(AND(L5="Among all respondents",NOT(OR(K5="Online poll in Telegram channel",K5="Website online poll",K5="CAWI (Computer Assisted Web Interviewing)"))),1/(1-MIN(MAX(Formula!$C$33+(YEAR(D5)-Formula!$C$34)/(Formula!$C$35-Formula!$C$34)*(Formula!$C$32-Formula!$C$33),Formula!$C$33),Formula!$C$32)),1) -> 1 | W5: =IF(ISNUMBER(N5),N5*V5,"") -> 7.4
A6: 2241:Igor Terehov | B6: 2241 | C6: https://ukraine-elections.com.ua/en/socopros/opinion_poll_show/2241 | D6: 2026-03-26 | E6: SOCIS | F6: Ukraine | G6: 2026-03-12 | H6: 2026-03-18 | I6: 1204 | J6: 2.5 | K6: CATI - computer-assisted telephone interviews | L6: Among those who will vote and have made their choice | M6: Igor Terehov | N6: 4.4 | O6: =DATE(YEAR(D6),MONTH(D6),1) -> 46082 | P6: =IFERROR(VLOOKUP(K6,Formula!$A$11:$B$20,2,FALSE),Formula!$C$26) -> 0.9 | Q6: =IF(AND(ISNUMBER(J6),J6>0),1/J6,IF(AND(ISNUMBER(I6),I6>0),SQRT(MIN(I6,Formula!$C$27))/Formula!$C$24,1/Formula!$C$25)) -> 0.4 | R6: =P6*Q6 -> 0.36 | S6: =IF(H6<>"",EXP(-Formula!$C$28*(EOMONTH(H6,0)-H6)),EXP(-Formula!$C$28*(EOMONTH(D6,0)-D6))) -> 0.52204578 | T6: =IFERROR(SQRT(1/COUNTIFS($E$2:$E$2277,E6,$O$2:$O$2277,O6)),1) -> 0.28867513 | U6: =P6*Q6*S6*T6 -> 0.054252589 | V6: =IF(AND(L6="Among all respondents",NOT(OR(K6="Online poll in Telegram channel",K6="Website online poll",K6="CAWI (Computer Assisted Web Interviewing)"))),1/(1-MIN(MAX(Formula!$C$33+(YEAR(D6)-Formula!$C$34)/(Formula!$C$35-Formula!$C$34)*(Formula!$C$32-Formula!$C$33),Formula!$C$33),Formula!$C$32)),1) -> 1 | W6: =IF(ISNUMBER(N6),N6*V6,"") -> 4.4
A7: 2241:Dmitriy Razumkov | B7: 2241 | C7: https://ukraine-elections.com.ua/en/socopros/opinion_poll_show/2241 | D7: 2026-03-26 | E7: SOCIS | F7: Ukraine | G7: 2026-03-12 | H7: 2026-03-18 | I7: 1204 | J7: 2.5 | K7: CATI - computer-assisted telephone interviews | L7: Among those who will vote and have made their choice | M7: Dmitriy Razumkov | N7: 4.3 | O7: =DATE(YEAR(D7),MONTH(D7),1) -> 46082 | P7: =IFERROR(VLOOKUP(K7,Formula!$A$11:$B$20,2,FALSE),Formula!$C$26) -> 0.9 | Q7: =IF(AND(ISNUMBER(J7),J7>0),1/J7,IF(AND(ISNUMBER(I7),I7>0),SQRT(MIN(I7,Formula!$C$27))/Formula!$C$24,1/Formula!$C$25)) -> 0.4 | R7: =P7*Q7 -> 0.36 | S7: =IF(H7<>"",EXP(-Formula!$C$28*(EOMONTH(H7,0)-H7)),EXP(-Formula!$C$28*(EOMONTH(D7,0)-D7))) -> 0.52204578 | T7: =IFERROR(SQRT(1/COUNTIFS($E$2:$E$2277,E7,$O$2:$O$2277,O7)),1) -> 0.28867513 | U7: =P7*Q7*S7*T7 -> 0.054252589 | V7: =IF(AND(L7="Among all respondents",NOT(OR(K7="Online poll in Telegram channel",K7="Website online poll",K7="CAWI (Computer Assisted Web Interviewing)"))),1/(1-MIN(MAX(Formula!$C$33+(YEAR(D7)-Formula!$C$34)/(Formula!$C$35-Formula!$C$34)*(Formula!$C$32-Formula!$C$33),Formula!$C$33),Formula!$C$32)),1) -> 1 | W7: =IF(ISNUMBER(N7),N7*V7,"") -> 4.3
A8: 2241:Andrei Bileckiy | B8: 2241 | C8: https://ukraine-elections.com.ua/en/socopros/opinion_poll_show/2241 | D8: 2026-03-26 | E8: SOCIS | F8: Ukraine | G8: 2026-03-12 | H8: 2026-03-18 | I8: 1204 | J8: 2.5 | K8: CATI - computer-assisted telephone interviews | L8: Among those who will vote and have made their choice | M8: Andrei Bileckiy | N8: 4 | O8: =DATE(YEAR(D8),MONTH(D8),1) -> 46082 | P8: =IFERROR(VLOOKUP(K8,Formula!$A$11:$B$20,2,FALSE),Formula!$C$26) -> 0.9 | Q8: =IF(AND(ISNUMBER(J8),J8>0),1/J8,IF(AND(ISNUMBER(I8),I8>0),SQRT(MIN(I8,Formula!$C$27))/Formula!$C$24,1/Formula!$C$25)) -> 0.4 | R8: =P8*Q8 -> 0.36 | S8: =IF(H8<>"",EXP(-Formula!$C$28*(EOMONTH(H8,0)-H8)),EXP(-Formula!$C$28*(EOMONTH(D8,0)-D8))) -> 0.52204578 | T8: =IFERROR(SQRT(1/COUNTIFS($E$2:$E$2277,E8,$O$2:$O$2277,O8)),1) -> 0.28867513 | U8: =P8*Q8*S8*T8 -> 0.054252589 | V8: =IF(AND(L8="Among all respondents",NOT(OR(K8="Online poll in Telegram channel",K8="Website online poll",K8="CAWI (Computer Assisted Web Interviewing)"))),1/(1-MIN(MAX(Formula!$C$33+(YEAR(D8)-Formula!$C$34)/(Formula!$C$35-Formula!$C$34)*(Formula!$C$32-Formula!$C$33),Formula!$C$33),Formula!$C$32)),1) -> 1 | W8: =IF(ISNUMBER(N8),N8*V8,"") -> 4
A9: 2241:Yulia Timoshenko | B9: 2241 | C9: https://ukraine-elections.com.ua/en/socopros/opinion_poll_show/2241 | D9: 2026-03-26 | E9: SOCIS | F9: Ukraine | G9: 2026-03-12 | H9: 2026-03-18 | I9: 1204 | J9: 2.5 | K9: CATI - computer-assisted telephone interviews | L9: Among those who will vote and have made their choice | M9: Yulia Timoshenko | N9: 2.9 | O9: =DATE(YEAR(D9),MONTH(D9),1) -> 46082 | P9: =IFERROR(VLOOKUP(K9,Formula!$A$11:$B$20,2,FALSE),Formula!$C$26) -> 0.9 | Q9: =IF(AND(ISNUMBER(J9),J9>0),1/J9,IF(AND(ISNUMBER(I9),I9>0),SQRT(MIN(I9,Formula!$C$27))/Formula!$C$24,1/Formula!$C$25)) -> 0.4 | R9: =P9*Q9 -> 0.36 | S9: =IF(H9<>"",EXP(-Formula!$C$28*(EOMONTH(H9,0)-H9)),EXP(-Formula!$C$28*(EOMONTH(D9,0)-D9))) -> 0.52204578 | T9: =IFERROR(SQRT(1/COUNTIFS($E$2:$E$2277,E9,$O$2:$O$2277,O9)),1) -> 0.28867513 | U9: =P9*Q9*S9*T9 -> 0.054252589 | V9: =IF(AND(L9="Among all respondents",NOT(OR(K9="Online poll in Telegram channel",K9="Website online poll",K9="CAWI (Computer Assisted Web Interviewing)"))),1/(1-MIN(MAX(Formula!$C$33+(YEAR(D9)-Formula!$C$34)/(Formula!$C$35-Formula!$C$34)*(Formula!$C$32-Formula!$C$33),Formula!$C$33),Formula!$C$32)),1) -> 1 | W9: =IF(ISNUMBER(N9),N9*V9,"") -> 2.9
A10: 2241:Sergey Pritula | B10: 2241 | C10: https://ukraine-elections.com.ua/en/socopros/opinion_poll_show/2241 | D10: 2026-03-26 | E10: SOCIS | F10: Ukraine | G10: 2026-03-12 | H10: 2026-03-18 | I10: 1204 | J10: 2.5 | K10: CATI - computer-assisted telephone interviews | L10: Among those who will vote and have made their choice | M10: Sergey Pritula | N10: 1.6 | O10: =DATE(YEAR(D10),MONTH(D10),1) -> 46082 | P10: =IFERROR(VLOOKUP(K10,Formula!$A$11:$B$20,2,FALSE),Formula!$C$26) -> 0.9 | Q10: =IF(AND(ISNUMBER(J10),J10>0),1/J10,IF(AND(ISNUMBER(I10),I10>0),SQRT(MIN(I10,Formula!$C$27))/Formula!$C$24,1/Formula!$C$25)) -> 0.4 | R10: =P10*Q10 -> 0.36 | S10: =IF(H10<>"",EXP(-Formula!$C$28*(EOMONTH(H10,0)-H10)),EXP(-Formula!$C$28*(EOMONTH(D10,0)-D10))) -> 0.52204578 | T10: =IFERROR(SQRT(1/COUNTIFS($E$2:$E$2277,E10,$O$2:$O$2277,O10)),1) -> 0.28867513 | U10: =P10*Q10*S10*T10 -> 0.054252589 | V10: =IF(AND(L10="Among all respondents",NOT(OR(K10="Online poll in Telegram channel",K10="Website online poll",K10="CAWI (Computer Assisted Web Interviewing)"))),1/(1-MIN(MAX(Formula!$C$33+(YEAR(D10)-Formula!$C$34)/(Formula!$C$35-Formula!$C$34)*(Formula!$C$32-Formula!$C$33),Formula!$C$33),Formula!$C$32)),1) -> 1 | W10: =IF(ISNUMBER(N10),N10*V10,"") -> 1.6
A11: 2241:Vitalii Kim | B11: 2241 | C11: https://ukraine-elections.com.ua/en/socopros/opinion_poll_show/2241 | D11: 2026-03-26 | E11: SOCIS | F11: Ukraine | G11: 2026-03-12 | H11: 2026-03-18 | I11: 1204 | J11: 2.5 | K11: CATI - computer-assisted telephone interviews | L11: Among those who will vote and have made their choice | M11: Vitalii Kim | N11: 1.4 | O11: =DATE(YEAR(D11),MONTH(D11),1) -> 46082 | P11: =IFERROR(VLOOKUP(K11,Formula!$A$11:$B$20,2,FALSE),Formula!$C$26) -> 0.9 | Q11: =IF(AND(ISNUMBER(J11),J11>0),1/J11,IF(AND(ISNUMBER(I11),I11>0),SQRT(MIN(I11,Formula!$C$27))/Formula!$C$24,1/Formula!$C$25)) -> 0.4 | R11: =P11*Q11 -> 0.36 | S11: =IF(H11<>"",EXP(-Formula!$C$28*(EOMONTH(H11,0)-H11)),EXP(-Formula!$C$28*(EOMONTH(D11,0)-D11))) -> 0.52204578 | T11: =IFERROR(SQRT(1/COUNTIFS($E$2:$E$2277,E11,$O$2:$O$2277,O11)),1) -> 0.28867513 | U11: =P11*Q11*S11*T11 -> 0.054252589 | V11: =IF(AND(L11="Among all respondents",NOT(OR(K11="Online poll in Telegram channel",K11="Website online poll",K11="CAWI (Computer Assisted Web Interviewing)"))),1/(1-MIN(MAX(Formula!$C$33+(YEAR(D11)-Formula!$C$34)/(Formula!$C$35-Formula!$C$34)*(Formula!$C$32-Formula!$C$33),Formula!$C$33),Formula!$C$32)),1) -> 1 | W11: =IF(ISNUMBER(N11),N11*V11,"") -> 1.4
A12: 2241:Vitaly Klichko | B12: 2241 | C12: https://ukraine-elections.com.ua/en/socopros/opinion_poll_show/2241 | D12: 2026-03-26 | E12: SOCIS | F12: Ukraine | G12: 2026-03-12 | H12: 2026-03-18 | I12: 1204 | J12: 2.5 | K12: CATI - computer-assisted telephone interviews | L12: Among those who will vote and have made their choice | M12: Vitaly Klichko | N12: 0.7 | O12: =DATE(YEAR(D12),MONTH(D12),1) -> 46082 | P12: =IFERROR(VLOOKUP(K12,Formula!$A$11:$B$20,2,FALSE),Formula!$C$26) -> 0.9 | Q12: =IF(AND(ISNUMBER(J12),J12>0),1/J12,IF(AND(ISNUMBER(I12),I12>0),SQRT(MIN(I12,Formula!$C$27))/Formula!$C$24,1/Formula!$C$25)) -> 0.4 | R12: =P12*Q12 -> 0.36 | S12: =IF(H12<>"",EXP(-Formula!$C$28*(EOMONTH(H12,0)-H12)),EXP(-Formula!$C$28*(EOMONTH(D12,0)-D12))) -> 0.52204578 | T12: =IFERROR(SQRT(1/COUNTIFS($E$2:$E$2277,E12,$O$2:$O$2277,O12)),1) -> 0.28867513 | U12: =P12*Q12*S12*T12 -> 0.054252589 | V12: =IF(AND(L12="Among all respondents",NOT(OR(K12="Online poll in Telegram channel",K12="Website online poll",K12="CAWI (Computer Assisted Web Interviewing)"))),1/(1-MIN(MAX(Formula!$C$33+(YEAR(D12)-Formula!$C$34)/(Formula!$C$35-Formula!$C$34)*(Formula!$C$32-Formula!$C$33),Formula!$C$33),Formula!$C$32)),1) -> 1 | W12: =IF(ISNUMBER(N12),N12*V12,"") -> 0.7
A13: 2241:Alexander Vilkul | B13: 2241 | C13: https://ukraine-elections.com.ua/en/socopros/opinion_poll_show/2241 | D13: 2026-03-26 | E13: SOCIS | F13: Ukraine | G13: 2026-03-12 | H13: 2026-03-18 | I13: 1204 | J13: 2.5 | K13: CATI - computer-assisted telephone interviews | L13: Among those who will vote and have made their choice | M13: Alexander Vilkul | N13: 0.6 | O13: =DATE(YEAR(D13),MONTH(D13),1) -> 46082 | P13: =IFERROR(VLOOKUP(K13,Formula!$A$11:$B$20,2,FALSE),Formula!$C$26) -> 0.9 | Q13: =IF(AND(ISNUMBER(J13),J13>0),1/J13,IF(AND(ISNUMBER(I13),I13>0),SQRT(MIN(I13,Formula!$C$27))/Formula!$C$24,1/Formula!$C$25)) -> 0.4 | R13: =P13*Q13 -> 0.36 | S13: =IF(H13<>"",EXP(-Formula!$C$28*(EOMONTH(H13,0)-H13)),EXP(-Formula!$C$28*(EOMONTH(D13,0)-D13))) -> 0.52204578 | T13: =IFERROR(SQRT(1/COUNTIFS($E$2:$E$2277,E13,$O$2:$O$2277,O13)),1) -> 0.28867513 | U13: =P13*Q13*S13*T13 -> 0.054252589 | V13: =IF(AND(L13="Among all respondents",NOT(OR(K13="Online poll in Telegram channel",K13="Website online poll",K13="CAWI (Computer Assisted Web Interviewing)"))),1/(1-MIN(MAX(Formula!$C$33+(YEAR(D13)-Formula!$C$34)/(Formula!$C$35-Formula!$C$34)*(Formula!$C$32-Formula!$C$33),Formula!$C$33),Formula!$C$32)),1) -> 1 | W13: =IF(ISNUMBER(N13),N13*V13,"") -> 0.6
... A54: 2228:Denis Prokopenko | B54: 2228 | C54: https://ukraine-elections.com.ua/en/socopros/opinion_poll_show/2228 | D54: 2026-01-12 | E54: Active Group | F54: Ukraine | G54: 2026-01-10 | H54: 2026-01-10 | I54: 800 | J54: 3.5 | K54: CAWI (Computer Assisted Web Interviewing) | L54: Among those who will vote and have made their choice | M54: Denis Prokopenko | N54: 1 | O54: =DATE(YEAR(D54),MONTH(D54),1) -> 46023 | P54: =IFERROR(VLOOKUP(K54,Formula!$A$11:$B$20,2,FALSE),Formula!$C$26) -> 0.6 | Q54: =IF(AND(ISNUMBER(J54),J54>0),1/J54,IF(AND(ISNUMBER(I54),I54>0),SQRT(MIN(I54,Formula!$C$27))/Formula!$C$24,1/Formula!$C$25)) -> 0.28571429 | R54: =P54*Q54 -> 0.17142857 | S54: =IF(H54<>"",EXP(-Formula!$C$28*(EOMONTH(H54,0)-H54)),EXP(-Formula!$C$28*(EOMONTH(D54,0)-D54))) -> 0.34993775 | T54: =IFERROR(SQRT(1/COUNTIFS($E$2:$E$2277,E54,$O$2:$O$2277,O54)),1) -> 0.2773501 | U54: =P54*Q54*S54*T54 -> 0.016638046 | V54: =IF(AND(L54="Among all respondents",NOT(OR(K54="Online poll in Telegram channel",K54="Website online poll",K54="CAWI (Computer Assisted Web Interviewing)"))),1/(1-MIN(MAX(Formula!$C$33+(YEAR(D54)-Formula!$C$34)/(Formula!$C$35-Formula!$C$34)*(Formula!$C$32-Formula!$C$33),Formula!$C$33),Formula!$C$32)),1) -> 1 | W54: =IF(ISNUMBER(N54),N54*V54,"") -> 1
A55: 2227:Valerii Zaluzhniy | B55: 2227 | C55: https://ukraine-elections.com.ua/en/socopros/opinion_poll_show/2227 | D55: 2026-01-02 | E55: Ipsos | F55: Ukraine | G55: 2025-12-31 | H55: 2025-12-31 | I55: 2000 | K55: CATI - computer-assisted telephone interviews | L55: Among all respondents | M55: Valerii Zaluzhniy | N55: 23 | O55: =DATE(YEAR(D55),MONTH(D55),1) -> 46023 | P55: =IFERROR(VLOOKUP(K55,Formula!$A$11:$B$20,2,FALSE),Formula!$C$26) -> 0.9 | Q55: =IF(AND(ISNUMBER(J55),J55>0),1/J55,IF(AND(ISNUMBER(I55),I55>0),SQRT(MIN(I55,Formula!$C$27))/Formula!$C$24,1/Formula!$C$25)) -> 0.4563404 | R55: =P55*Q55 -> 0.41070636 | S55: =IF(H55<>"",EXP(-Formula!$C$28*(EOMONTH(H55,0)-H55)),EXP(-Formula!$C$28*(EOMONTH(D55,0)-D55))) -> 1 | T55: =IFERROR(SQRT(1/COUNTIFS($E$2:$E$2277,E55,$O$2:$O$2277,O55)),1) -> 0.5 | U55: =P55*Q55*S55*T55 -> 0.20535318 | V55: =IF(AND(L55="Among all respondents",NOT(OR(K55="Online poll in Telegram channel",K55="Website online poll",K55="CAWI (Computer Assisted Web Interviewing)"))),1/(1-MIN(MAX(Formula!$C$33+(YEAR(D55)-Formula!$C$34)/(Formula!$C$35-Formula!$C$34)*(Formula!$C$32-Formula!$C$33),Formula!$C$33),Formula!$C$32)),1) -> 1.2820513 | W55: =IF(ISNUMBER(N55),N55*V55,"") -> 29.487179
A56: 2227:Vladimir Zelenskiy | B56: 2227 | C56: https://ukraine-elections.com.ua/en/socopros/opinion_poll_show/2227 | D56: 2026-01-02 | E56: Ipsos | F56: Ukraine | G56: 2025-12-31 | H56: 2025-12-31 | I56: 2000 | K56: CATI - computer-assisted telephone interviews | L56: Among all respondents | M56: Vladimir Zelenskiy | N56: 20 | O56: =DATE(YEAR(D56),MONTH(D56),1) -> 46023 | P56: =IFERROR(VLOOKUP(K56,Formula!$A$11:$B$20,2,FALSE),Formula!$C$26) -> 0.9 | Q56: =IF(AND(ISNUMBER(J56),J56>0),1/J56,IF(AND(ISNUMBER(I56),I56>0),SQRT(MIN(I56,Formula!$C$27))/Formula!$C$24,1/Formula!$C$25)) -> 0.4563404 | R56: =P56*Q56 -> 0.41070636 | S56: =IF(H56<>"",EXP(-Formula!$C$28*(EOMONTH(H56,0)-H56)),EXP(-Formula!$C$28*(EOMONTH(D56,0)-D56))) -> 1 | T56: =IFERROR(SQRT(1/COUNTIFS($E$2:$E$2277,E56,$O$2:$O$2277,O56)),1) -> 0.5 | U56: =P56*Q56*S56*T56 -> 0.20535318 | V56: =IF(AND(L56="Among all respondents",NOT(OR(K56="Online poll in Telegram channel",K56="Website online poll",K56="CAWI (Computer Assisted Web Interviewing)"))),1/(1-MIN(MAX(Formula!$C$33+(YEAR(D56)-Formula!$C$34)/(Formula!$C$35-Formula!$C$34)*(Formula!$C$32-Formula!$C$33),Formula!$C$33),Formula!$C$32)),1) -> 1.2820513 | W56: =IF(ISNUMBER(N56),N56*V56,"") -> 25.641026
A57: 2227:Pyotr Poroshenko | B57: 2227 | C57: https://ukraine-elections.com.ua/en/socopros/opinion_poll_show/2227 | D57: 2026-01-02 | E57: Ipsos | F57: Ukraine | G57: 2025-12-31 | H57: 2025-12-31 | I57: 2000 | K57: CATI - computer-assisted telephone interviews | L57: Among all respondents | M57: Pyotr Poroshenko | N57: 9 | O57: =DATE(YEAR(D57),MONTH(D57),1) -> 46023 | P57: =IFERROR(VLOOKUP(K57,Formula!$A$11:$B$20,2,FALSE),Formula!$C$26) -> 0.9 | Q57: =IF(AND(ISNUMBER(J57),J57>0),1/J57,IF(AND(ISNUMBER(I57),I57>0),SQRT(MIN(I57,Formula!$C$27))/Formula!$C$24,1/Formula!$C$25)) -> 0.4563404 | R57: =P57*Q57 -> 0.41070636 | S57: =IF(H57<>"",EXP(-Formula!$C$28*(EOMONTH(H57,0)-H57)),EXP(-Formula!$C$28*(EOMONTH(D57,0)-D57))) -> 1 | T57: =IFERROR(SQRT(1/COUNTIFS($E$2:$E$2277,E57,$O$2:$O$2277,O57)),1) -> 0.5 | U57: =P57*Q57*S57*T57 -> 0.20535318 | V57: =IF(AND(L57="Among all respondents",NOT(OR(K57="Online poll in Telegram channel",K57="Website online poll",K57="CAWI (Computer Assisted Web Interviewing)"))),1/(1-MIN(MAX(Formula!$C$33+(YEAR(D57)-Formula!$C$34)/(Formula!$C$35-Formula!$C$34)*(Formula!$C$32-Formula!$C$33),Formula!$C$33),Formula!$C$32)),1) -> 1.2820513 | W57: =IF(ISNUMBER(N57),N57*V57,"") -> 11.538462
A58: 2227:Kyrylo Budanov | B58: 2227 | C58: https://ukraine-elections.com.ua/en/socopros/opinion_poll_show/2227 | D58: 2026-01-02 | E58: Ipsos | F58: Ukraine | G58: 2025-12-31 | H58: 2025-12-31 | I58: 2000 | K58: CATI - computer-assisted telephone interviews | L58: Among all respondents | M58: Kyrylo Budanov | N58: 7 | O58: =DATE(YEAR(D58),MONTH(D58),1) -> 46023 | P58: =IFERROR(VLOOKUP(K58,Formula!$A$11:$B$20,2,FALSE),Formula!$C$26) -> 0.9 | Q58: =IF(AND(ISNUMBER(J58),J58>0),1/J58,IF(AND(ISNUMBER(I58),I58>0),SQRT(MIN(I58,Formula!$C$27))/Formula!$C$24,1/Formula!$C$25)) -> 0.4563404 | R58: =P58*Q58 -> 0.41070636 | S58: =IF(H58<>"",EXP(-Formula!$C$28*(EOMONTH(H58,0)-H58)),EXP(-Formula!$C$28*(EOMONTH(D58,0)-D58))) -> 1 | T58: =IFERROR(SQRT(1/COUNTIFS($E$2:$E$2277,E58,$O$2:$O$2277,O58)),1) -> 0.5 | U58: =P58*Q58*S58*T58 -> 0.20535318 | V58: =IF(AND(L58="Among all respondents",NOT(OR(K58="Online poll in Telegram channel",K58="Website online poll",K58="CAWI (Computer Assisted Web Interviewing)"))),1/(1-MIN(MAX(Formula!$C$33+(YEAR(D58)-Formula!$C$34)/(Formula!$C$35-Formula!$C$34)*(Formula!$C$32-Formula!$C$33),Formula!$C$33),Formula!$C$32)),1) -> 1.2820513 | W58: =IF(ISNUMBER(N58),N58*V58,"") -> 8.974359
A59: 2226:Vladimir Zelenskiy | B59: 2226 | C59: https://ukraine-elections.com.ua/en/socopros/opinion_poll_show/2226 | D59: 2025-12-29 | E59: Active Group | F59: Ukraine | G59: 2025-12-21 | H59: 2025-12-23 | I59: 2000 | J59: 2.2 | K59: CAWI (Computer Assisted Web Interviewing) | L59: Among those who will vote and have made their choice | M59: Vladimir Zelenskiy | N59: 26.8 | O59: =DATE(YEAR(D59),MONTH(D59),1) -> 45992 | P59: =IFERROR(VLOOKUP(K59,Formula!$A$11:$B$20,2,FALSE),Formula!$C$26) -> 0.6 | Q59: =IF(AND(ISNUMBER(J59),J59>0),1/J59,IF(AND(ISNUMBER(I59),I59>0),SQRT(MIN(I59,Formula!$C$27))/Formula!$C$24,1/Formula!$C$25)) -> 0.45454545 | R59: =P59*Q59 -> 0.27272727 | S59: =IF(H59<>"",EXP(-Formula!$C$28*(EOMONTH(H59,0)-H59)),EXP(-Formula!$C$28*(EOMONTH(D59,0)-D59))) -> 0.67032005 | T59: =IFERROR(SQRT(1/COUNTIFS($E$2:$E$2277,E59,$O$2:$O$2277,O59)),1) -> 0.2773501 | U59: =P59*Q59*S59*T59 -> 0.050703636 | V59: =IF(AND(L59="Among all respondents",NOT(OR(K59="Online poll in Telegram channel",K59="Website online poll",K59="CAWI (Computer Assisted Web Interviewing)"))),1/(1-MIN(MAX(Formula!$C$33+(YEAR(D59)-Formula!$C$34)/(Formula!$C$35-Formula!$C$34)*(Formula!$C$32-Formula!$C$33),Formula!$C$33),Formula!$C$32)),1) -> 1 | W59: =IF(ISNUMBER(N59),N59*V59,"") -> 26.8
A60: 2226:Valerii Zaluzhniy | B60: 2226 | C60: https://ukraine-elections.com.ua/en/socopros/opinion_poll_show/2226 | D60: 2025-12-29 | E60: Active Group | F60: Ukraine | G60: 2025-12-21 | H60: 2025-12-23 | I60: 2000 | J60: 2.2 | K60: CAWI (Computer Assisted Web Interviewing) | L60: Among those who will vote and have made their choice | M60: Valerii Zaluzhniy | N60: 25.1 | O60: =DATE(YEAR(D60),MONTH(D60),1) -> 45992 | P60: =IFERROR(VLOOKUP(K60,Formula!$A$11:$B$20,2,FALSE),Formula!$C$26) -> 0.6 | Q60: =IF(AND(ISNUMBER(J60),J60>0),1/J60,IF(AND(ISNUMBER(I60),I60>0),SQRT(MIN(I60,Formula!$C$27))/Formula!$C$24,1/Formula!$C$25)) -> 0.45454545 | R60: =P60*Q60 -> 0.27272727 | S60: =IF(H60<>"",EXP(-Formula!$C$28*(EOMONTH(H60,0)-H60)),EXP(-Formula!$C$28*(EOMONTH(D60,0)-D60))) -> 0.67032005 | T60: =IFERROR(SQRT(1/COUNTIFS($E$2:$E$2277,E60,$O$2:$O$2277,O60)),1) -> 0.2773501 | U60: =P60*Q60*S60*T60 -> 0.050703636 | V60: =IF(AND(L60="Among all respondents",NOT(OR(K60="Online poll in Telegram channel",K60="Website online poll",K60="CAWI (Computer Assisted Web Interviewing)"))),1/(1-MIN(MAX(Formula!$C$33+(YEAR(D60)-Formula!$C$34)/(Formula!$C$35-Formula!$C$34)*(Formula!$C$32-Formula!$C$33),Formula!$C$33),Formula!$C$32)),1) -> 1 | W60: =IF(ISNUMBER(N60),N60*V60,"") -> 25.1
A61: 2226:Kyrylo Budanov | B61: 2226 | C61: https://ukraine-elections.com.ua/en/socopros/opinion_poll_show/2226 | D61: 2025-12-29 | E61: Active Group | F61: Ukraine | G61: 2025-12-21 | H61: 2025-12-23 | I61: 2000 | J61: 2.2 | K61: CAWI (Computer Assisted Web Interviewing) | L61: Among those who will vote and have made their choice | M61: Kyrylo Budanov | N61: 10.9 | O61: =DATE(YEAR(D61),MONTH(D61),1) -> 45992 | P61: =IFERROR(VLOOKUP(K61,Formula!$A$11:$B$20,2,FALSE),Formula!$C$26) -> 0.6 | Q61: =IF(AND(ISNUMBER(J61),J61>0),1/J61,IF(AND(ISNUMBER(I61),I61>0),SQRT(MIN(I61,Formula!$C$27))/Formula!$C$24,1/Formula!$C$25)) -> 0.45454545 | R61: =P61*Q61 -> 0.27272727 | S61: =IF(H61<>"",EXP(-Formula!$C$28*(EOMONTH(H61,0)-H61)),EXP(-Formula!$C$28*(EOMONTH(D61,0)-D61))) -> 0.67032005 | T61: =IFERROR(SQRT(1/COUNTIFS($E$2:$E$2277,E61,$O$2:$O$2277,O61)),1) -> 0.2773501 | U61: =P61*Q61*S61*T61 -> 0.050703636 | V61: =IF(AND(L61="Among all respondents",NOT(OR(K61="Online poll in Telegram channel",K61="Website online poll",K61="CAWI (Computer Assisted Web Interviewing)"))),1/(1-MIN(MAX(Formula!$C$33+(YEAR(D61)-Formula!$C$34)/(Formula!$C$35-Formula!$C$34)*(Formula!$C$32-Formula!$C$33),Formula!$C$33),Formula!$C$32)),1) -> 1 | W61: =IF(ISNUMBER(N61),N61*V61,"") -> 10.9
A62: 2226:Pyotr Poroshenko | B62: 2226 | C62: https://ukraine-elections.com.ua/en/socopros/opinion_poll_show/2226 | D62: 2025-12-29 | E62: Active Group | F62: Ukraine | G62: 2025-12-21 | H62: 2025-12-23 | I62: 2000 | J62: 2.2 | K62: CAWI (Computer Assisted Web Interviewing) | L62: Among those who will vote and have made their choice | M62: Pyotr Poroshenko | N62: 9.8 | O62: =DATE(YEAR(D62),MONTH(D62),1) -> 45992 | P62: =IFERROR(VLOOKUP(K62,Formula!$A$11:$B$20,2,FALSE),Formula!$C$26) -> 0.6 | Q62: =IF(AND(ISNUMBER(J62),J62>0),1/J62,IF(AND(ISNUMBER(I62),I62>0),SQRT(MIN(I62,Formula!$C$27))/Formula!$C$24,1/Formula!$C$25)) -> 0.45454545 | R62: =P62*Q62 -> 0.27272727 | S62: =IF(H62<>"",EXP(-Formula!$C$28*(EOMONTH(H62,0)-H62)),EXP(-Formula!$C$28*(EOMONTH(D62,0)-D62))) -> 0.67032005 | T62: =IFERROR(SQRT(1/COUNTIFS($E$2:$E$2277,E62,$O$2:$O$2277,O62)),1) -> 0.2773501 | U62: =P62*Q62*S62*T62 -> 0.050703636 | V62: =IF(AND(L62="Among all respondents",NOT(OR(K62="Online poll in Telegram channel",K62="Website online poll",K62="CAWI (Computer Assisted Web Interviewing)"))),1/(1-MIN(MAX(Formula!$C$33+(YEAR(D62)-Formula!$C$34)/(Formula!$C$35-Formula!$C$34)*(Formula!$C$32-Formula!$C$33),Formula!$C$33),Formula!$C$32)),1) -> 1 | W62: =IF(ISNUMBER(N62),N62*V62,"") -> 9.8
A63: 2226:Dmitriy Razumkov | B63: 2226 | C63: https://ukraine-elections.com.ua/en/socopros/opinion_poll_show/2226 | D63: 2025-12-29 | E63: Active Group | F63: Ukraine | G63: 2025-12-21 | H63: 2025-12-23 | I63: 2000 | J63: 2.2 | K63: CAWI (Computer Assisted Web Interviewing) | L63: Among those who will vote and have made their choice | M63: Dmitriy Razumkov | N63: 8.1 | O63: =DATE(YEAR(D63),MONTH(D63),1) -> 45992 | P63: =IFERROR(VLOOKUP(K63,Formula!$A$11:$B$20,2,FALSE),Formula!$C$26) -> 0.6 | Q63: =IF(AND(ISNUMBER(J63),J63>0),1/J63,IF(AND(ISNUMBER(I63),I63>0),SQRT(MIN(I63,Formula!$C$27))/Formula!$C$24,1/Formula!$C$25)) -> 0.45454545 | R63: =P63*Q63 -> 0.27272727 | S63: =IF(H63<>"",EXP(-Formula!$C$28*(EOMONTH(H63,0)-H63)),EXP(-Formula!$C$28*(EOMONTH(D63,0)-D63))) -> 0.67032005 | T63: =IFERROR(SQRT(1/COUNTIFS($E$2:$E$2277,E63,$O$2:$O$2277,O63)),1) -> 0.2773501 | U63: =P63*Q63*S63*T63 -> 0.050703636 | V63: =IF(AND(L63="Among all respondents",NOT(OR(K63="Online poll in Telegram channel",K63="Website online poll",K63="CAWI (Computer Assisted Web Interviewing)"))),1/(1-MIN(MAX(Formula!$C$33+(YEAR(D63)-Formula!$C$34)/(Formula!$C$35-Formula!$C$34)*(Formula!$C$32-Formula!$C$33),Formula!$C$33),Formula!$C$32)),1) -> 1 | W63: =IF(ISNUMBER(N63),N63*V63,"") -> 8.1
